Workbook

Sheet Executive Summary
A2: x | B2: Executive Summary
B3: Portfolio outsourced TAM, FY2022-31, constant FY2026 $M
A6: x | B6: §1 - Scope
B8: Question | C8: Portfolio outsourced new-construction TAM
B9: Definition | C9: BC base x supplier coefficient, plus applicable overlays
B10: Programs | C10: Virginia, Columbia, DDG-51
B11: Window | C11: FY2022-31, constant FY2026 $M
A14: x | B14: §2 - FY2022-27 outsourced TAM ($M)
B16: Program | C16: FY2022 | D16: FY2023 | E16: FY2024 | F16: FY2025 | G16: FY2026E | H16: FY2027E | I16: BC coeff
B17: Virginia | C17: ='Virginia TAM'!C25 | D17: ='Virginia TAM'!D25 | E17: ='Virginia TAM'!E25 | F17: ='Virginia TAM'!F25 | G17: ='Virginia TAM'!G25 | H17: ='Virginia TAM'!H25 | I17: ='Virginia TAM'!C34
B18: Columbia | C18: ='Columbia TAM'!C22 | D18: ='Columbia TAM'!D22 | E18: ='Columbia TAM'!E22 | F18: ='Columbia TAM'!F22 | G18: ='Columbia TAM'!G22 | H18: ='Columbia TAM'!H22 | I18: ='Columbia TAM'!C30
B19: DDG-51 | C19: ='DDG-51 TAM'!C28 | D19: ='DDG-51 TAM'!D28 | E19: ='DDG-51 TAM'!E28 | F19: ='DDG-51 TAM'!F28 | G19: ='DDG-51 TAM'!G28 | H19: ='DDG-51 TAM'!H28 | I19: ='DDG-51 TAM'!C38
B20: Total | C20: =SUM(C17:C19) | D20: =SUM(D17:D19) | E20: =SUM(E17:E19) | F20: =SUM(F17:F19) | G20: =SUM(G17:G19) | H20: =SUM(H17:H19)
B21: E = estimate: FY2026-27 budget request (FY2026 incl. OBBBA).
A24: x | B24: §3 - FY2028-31 outlook ($M)
B26: Outyear ($M) | C26: FY2028E | D26: FY2029E | E26: FY2030E | F26: FY2031E
B27: Virginia low | C27: ='Virginia TAM'!C56 | D27: ='Virginia TAM'!D56 | E27: ='Virginia TAM'!E56 | F27: ='Virginia TAM'!F56
B28: Columbia low | C28: ='Columbia TAM'!C51 | D28: ='Columbia TAM'!D51 | E28: ='Columbia TAM'!E51 | F28: ='Columbia TAM'!F51
B29: DDG-51 low | C29: ='DDG-51 TAM'!C62 | D29: ='DDG-51 TAM'!D62 | E29: ='DDG-51 TAM'!E62 | F29: ='DDG-51 TAM'!F62
B30: Total low | C30: =SUM(C27:C29) | D30: =SUM(D27:D29) | E30: =SUM(E27:E29) | F30: =SUM(F27:F29)
B31: Virginia high | C31: ='Virginia TAM'!C57 | D31: ='Virginia TAM'!D57 | E31: ='Virginia TAM'!E57 | F31: ='Virginia TAM'!F57
B32: Columbia high | C32: ='Columbia TAM'!C52 | D32: ='Columbia TAM'!D52 | E32: ='Columbia TAM'!E52 | F32: ='Columbia TAM'!F52
B33: DDG-51 high | C33: ='DDG-51 TAM'!C63 | D33: ='DDG-51 TAM'!D63 | E33: ='DDG-51 TAM'!E63 | F33: ='DDG-51 TAM'!F63
B34: Total high | C34: =SUM(C31:C33) | D34: =SUM(D31:D33) | E34: =SUM(E31:E33) | F34: =SUM(F31:F33)
B35: Low holds coefficients flat; high applies Assumptions §4.

Sheet Methodology
A2: x | B2: Methodology
B3: TAM definition, formula, scope, coefficient basis, and sources
A6: x | B6: §1 - Scope
B8: Question | C8: Supplier-addressable TAM for Virginia, Columbia, and DDG-51 new construction.
B9: Market | C9: New-construction work outsourced away from the prime/co-prime yards.
B10: Basis | C10: Built from SCN budget + DoD award place-of-performance, not sparse subawards.
A13: x | B13: §2 - Formula
B15: TAM = BC base x BC coeff + OBBBA BC base x BC coeff + AP/LLTM base x AP coeff
B16: BC base | C16: P-5c Basic Construction $/program/FY (SCN Budget), constant FY2026 $; GFE excluded.
B17: BC coefficient | C17: Award $-share landing away from the prime/co-prime yards (Place of Performance).
B18: OBBBA BC base | C18: BC slice of the OBBBA mandatory award (gross x BC share).
B19: AP/LLTM | C19: DDG only: P-10 Ship Construction EOQ x AP coeff (subs hold LLTM inside BC).
A22: x | B22: §3 - Coefficients
B24: Virginia (~34%) | C24: $-weighted Block V master (33% + 1%) + disclosed announcements; master dominates.
B25: Columbia (~22%) | C25: Build I construction master (other-US 22% + foreign 0%).
B26: DDG-51 (~25.3%) | C26: MYP-corrected FY23-27 masters + disclosed corpus; FY2022 uses FY18-22 vintage (~22%).
A29: x | B29: §4 - Sources
B31: Source | C31: Use
B32: PB2027 SCN P-5c | C32: BC base + cost-category breakdown (SCN Budget)
B33: PB2027 SCN P-40 | C33: FY2025-31 FYDP outyears (FYDP Outyears)
B34: PB2027 SCN P-10 | C34: DDG Ship Construction EOQ (AP/LLTM base)
B35: DoD award announcements | C35: place-of-performance corpus + construction masters
B36: Virginia Block V / Columbia Build I | C36: submarine applied BC coefficients
B37: DDG MYP awards | C37: DDG applied BC coefficient (MYP-corrected)
B38: OBBBA Sec. 20002 | C38: mandatory new-construction overlay (OBBBA Mandatory)
B39: Green Book Table 5-4 | C39: constant-FY2026 deflators (Deflators)

Sheet Assumptions
A2: x | B2: Assumptions
B3: Editable supplier-share, OBBBA, and outyear assumptions
A6: x | B6: §2 - DDG AP/LLTM supplier coefficient
B8: Knob | C8: Value
B9: DDG AP/LLTM supplier coefficient | C9: 1
A12: x | B12: §3 - OBBBA BC shares
B14: Control | C14: Observed | D14: Adjustment | E14: Modeled
B15: Virginia OBBBA BC share (Sec. 20002(16)) | C15: ='SCN Budget'!G34 | D15: 0 | E15: =C15+D15
B16: DDG-51 OBBBA BC share (Sec. 20002(17)) | C16: 0.628 | D16: 0 | E16: =C16+D16
B18: FY2027 execution spillover | C18: 0
A21: x | B21: §4 - Outyear intensity growth
B23: Knob | C23: Value
B24: HII outsourcing-hours growth | C24: 0.3
B25: HII shipbuilding-throughput growth | C25: 0.15
B26: Outsourcing intensity growth | C26: =(1+C24)/(1+C25)-1
B27: DDG-51 HII share of BC | C27: 0.55

Sheet Virginia TAM
A2: x | B2: Virginia TAM
B3: Virginia BC and OBBBA TAM, FY2022-31
A6: x | B6: §1 - Headline TAM
B8: Measure | C8: Value
B9: Cumulative TAM (FY22-27) $M | C9: =C31
B10: Average annual TAM $M/yr | C10: =C32
B11: Applied BC supplier coefficient | C11: =C34
B12: incl. OBBBA mandatory TAM $M | C12: =C33
B13: Implied outyear (FY28-31) low $M/yr | C13: =C59
B14: Implied outyear (FY28-31) high $M/yr | C14: =C60
A17: x | B17: §2 - TAM by fiscal year ($M, constant FY2026)
B19: Metric | C19: FY2022 | D19: FY2023 | E19: FY2024 | F19: FY2025 | G19: FY2026 | H19: FY2027 | I19: FY22-27
B20: BC base (P-5c Basic Construction) | C20: ='SCN Budget'!C50 | D20: ='SCN Budget'!D50 | E20: ='SCN Budget'!E50 | F20: ='SCN Budget'!F50 | G20: ='SCN Budget'!G50 | H20: ='SCN Budget'!H50 | I20: =SUM(C20:H20)
B21: OBBBA mandatory BC base | C21: ='OBBBA Mandatory'!C24 | D21: ='OBBBA Mandatory'!D24 | E21: ='OBBBA Mandatory'!E24 | F21: ='OBBBA Mandatory'!F24 | G21: ='OBBBA Mandatory'!G24 | H21: ='OBBBA Mandatory'!H24 | I21: =SUM(C21:H21)
B22: Applied BC coefficient (from Place of Performance) | C22: ='Place of Performance'!E11 | D22: ='Place of Performance'!E11 | E22: ='Place of Performance'!E11 | F22: ='Place of Performance'!E11 | G22: ='Place of Performance'!E11 | H22: ='Place of Performance'!E11
B23: TAM - BC stream | C23: =C20*C$22 | D23: =D20*D$22 | E23: =E20*E$22 | F23: =F20*F$22 | G23: =G20*G$22 | H23: =H20*H$22 | I23: =SUM(C23:H23)
B24: TAM - OBBBA mandatory stream | C24: =C21*C$22 | D24: =D21*D$22 | E24: =E21*E$22 | F24: =F21*F$22 | G24: =G21*G$22 | H24: =H21*H$22 | I24: =SUM(C24:H24)
B25: TAM (all streams) | C25: =SUM(C23:C24) | D25: =SUM(D23:D24) | E25: =SUM(E23:E24) | F25: =SUM(F23:F24) | G25: =SUM(G23:G24) | H25: =SUM(H23:H24) | I25: =SUM(C25:H25)
A28: x | B28: §2a - Roll-up & applied coefficient
B30: Measure | C30: Value
B31: Cumulative TAM (FY22-27) $M | C31: =I25
B32: Average annual TAM $M/yr | C32: =C31/6
B33: of which OBBBA mandatory TAM (cumulative) $M | C33: =I24
B34: Applied BC supplier coefficient | C34: ='Place of Performance'!E11
A37: x | B37: §3 - Penetration and outyears ($M)
B39: Metric | C39: FY2022 | D39: FY2023 | E39: FY2024 | F39: FY2025 | G39: FY2026 | H39: FY2027
B40: Outsourced TAM, all streams ($M) | C40: =N(C25) | D40: =N(D25) | E40: =N(E25) | F40: =N(F25) | G40: =N(G25) | H40: =N(H25)
B41: Total ship spend: P-5c Total Ship Estimate ($M) | C41: ='SCN Budget'!C40 | D41: ='SCN Budget'!D40 | E41: ='SCN Budget'!E40 | F41: ='SCN Budget'!F40 | G41: ='SCN Budget'!G40 | H41: ='SCN Budget'!H40
B42: plus OBBBA gross award ($M; FY27 via spillover) | C42: ='OBBBA Mandatory'!C18 | D42: ='OBBBA Mandatory'!D18 | E42: ='OBBBA Mandatory'!E18 | F42: ='OBBBA Mandatory'!F18 | G42: ='OBBBA Mandatory'!G18 | H42: ='OBBBA Mandatory'!H18
B43: Total ship spend incl. OBBBA ($M) | C43: =C41+N(C42) | D43: =D41+N(D42) | E43: =E41+N(E42) | F43: =F41+N(F42) | G43: =G41+N(G42) | H43: =H41+N(H42)
B44: Penetration: TAM / total ship spend | C44: =IF(C43=0,"",C40/C43) | D44: =IF(D43=0,"",D40/D43) | E44: =IF(E43=0,"",E40/E43) | F44: =IF(F43=0,"",F40/F43) | G44: =IF(G43=0,"",G40/G43) | H44: =IF(H43=0,"",H40/H43)
B46: Measure | C46: Value
B47: FY22-25 average penetration | C47: =SUM(C40:F40)/SUM(C43:F43)
B48: Forecast BC share | C48: =SUM(C20:F20)/SUM(C41:F41)
B49: Outyear BC coefficient, low | C49: ='Place of Performance'!E11
B50: Outsourcing intensity growth | C50: ='Assumptions'!C26
B51: Outyear BC coefficient, high | C51: =C49*(1+C50)
B53: Outyear ($M) | C53: FY2028 | D53: FY2029 | E53: FY2030 | F53: FY2031
B54: FYDP gross | C54: ='FYDP Outyears'!F42 | D54: ='FYDP Outyears'!G42 | E54: ='FYDP Outyears'!H42 | F54: ='FYDP Outyears'!I42
B55: Outyear BC base | C55: =C54*$C$48 | D55: =D54*$C$48 | E55: =E54*$C$48 | F55: =F54*$C$48
...

Sheet Columbia TAM
A2: x | B2: Columbia TAM
B3: Columbia BC TAM, FY2022-31
A6: x | B6: §1 - Headline TAM
B8: Measure | C8: Value
B9: Cumulative TAM (FY22-27) $M | C9: =C28
B10: Average annual TAM $M/yr | C10: =C29
B11: Applied BC supplier coefficient | C11: =C30
B12: Implied outyear (FY28-31) low $M/yr | C12: =C54
B13: Implied outyear (FY28-31) high $M/yr | C13: =C55
A16: x | B16: §2 - TAM by fiscal year ($M, constant FY2026)
B18: Metric | C18: FY2022 | D18: FY2023 | E18: FY2024 | F18: FY2025 | G18: FY2026 | H18: FY2027 | I18: FY22-27
B19: BC base (P-5c Basic Construction) | C19: ='SCN Budget'!C87 | D19: ='SCN Budget'!D87 | E19: ='SCN Budget'!E87 | F19: ='SCN Budget'!F87 | G19: ='SCN Budget'!G87 | H19: ='SCN Budget'!H87 | I19: =SUM(C19:H19)
B20: Applied BC coefficient (from Place of Performance) | C20: ='Place of Performance'!E12 | D20: ='Place of Performance'!E12 | E20: ='Place of Performance'!E12 | F20: ='Place of Performance'!E12 | G20: ='Place of Performance'!E12 | H20: ='Place of Performance'!E12
B21: TAM - BC stream | C21: =C19*C$20 | D21: =D19*D$20 | E21: =E19*E$20 | F21: =F19*F$20 | G21: =G19*G$20 | H21: =H19*H$20 | I21: =SUM(C21:H21)
B22: TAM (all streams) | C22: =SUM(C21:C21) | D22: =SUM(D21:D21) | E22: =SUM(E21:E21) | F22: =SUM(F21:F21) | G22: =SUM(G21:G21) | H22: =SUM(H21:H21) | I22: =SUM(C22:H22)
A25: x | B25: §2a - Roll-up & applied coefficient
B27: Measure | C27: Value
B28: Cumulative TAM (FY22-27) $M | C28: =I22
B29: Average annual TAM $M/yr | C29: =C28/6
B30: Applied BC supplier coefficient | C30: ='Place of Performance'!E12
A33: x | B33: §3 - Penetration and outyears ($M)
B35: Metric | C35: FY2022 | D35: FY2023 | E35: FY2024 | F35: FY2025 | G35: FY2026 | H35: FY2027
B36: Outsourced TAM, all streams ($M) | C36: =N(C22) | D36: =N(D22) | E36: =N(E22) | F36: =N(F22) | G36: =N(G22) | H36: =N(H22)
B37: Total ship spend: P-5c Total Ship Estimate ($M) | C37: ='SCN Budget'!C77 | D37: ='SCN Budget'!D77 | E37: ='SCN Budget'!E77 | F37: ='SCN Budget'!F77 | G37: ='SCN Budget'!G77 | H37: ='SCN Budget'!H77
B38: Total ship spend ($M) | C38: =N(C37) | D38: =N(D37) | E38: =N(E37) | F38: =N(F37) | G38: =N(G37) | H38: =N(H37)
B39: Penetration: TAM / total ship spend | C39: =IF(C38=0,"",C36/C38) | D39: =IF(D38=0,"",D36/D38) | E39: =IF(E38=0,"",E36/E38) | F39: =IF(F38=0,"",F36/F38) | G39: =IF(G38=0,"",G36/G38) | H39: =IF(H38=0,"",H36/H38)
B41: Measure | C41: Value
B42: FY22-25 average penetration | C42: =SUM(C36:F36)/SUM(C38:F38)
B43: Forecast BC share | C43: =SUM(C19:F19)/SUM(C37:F37)
B44: Outyear BC coefficient, low | C44: ='Place of Performance'!E12
B45: Outsourcing intensity growth | C45: ='Assumptions'!C26
B46: Outyear BC coefficient, high | C46: =C44*(1+C45)
B48: Outyear ($M) | C48: FY2028 | D48: FY2029 | E48: FY2030 | F48: FY2031
B49: FYDP gross | C49: ='FYDP Outyears'!F43 | D49: ='FYDP Outyears'!G43 | E49: ='FYDP Outyears'!H43 | F49: ='FYDP Outyears'!I43
B50: Outyear BC base | C50: =C49*$C$43 | D50: =D49*$C$43 | E50: =E49*$C$43 | F50: =F49*$C$43
B51: Outsourced BC, low | C51: =C50*$C$44 | D51: =D50*$C$44 | E51: =E50*$C$44 | F51: =F50*$C$44
B52: Outsourced BC, high | C52: =C50*$C$46 | D52: =D50*$C$46 | E52: =E50*$C$46 | F52: =F50*$C$46
B54: Outyear low average | C54: =AVERAGE(C51:F51)
B55: Outyear high average | C55: =AVERAGE(C52:F52)

Sheet DDG-51 TAM
A2: x | B2: DDG-51 TAM
B3: DDG-51 BC, AP/LLTM, and OBBBA TAM, FY2022-31
A6: x | B6: §1 - Headline TAM
B8: Measure | C8: Value
B9: Cumulative TAM (FY22-27) $M | C9: =C34
B10: Average annual TAM $M/yr | C10: =C35
B11: Applied BC supplier coefficient | C11: =C38
B12: incl. OBBBA mandatory TAM $M | C12: =C36
B13: incl. AP/LLTM TAM $M | C13: =I27
B14: Implied outyear (FY28-31) low $M/yr | C14: =C65
B15: Implied outyear (FY28-31) high $M/yr | C15: =C66
A18: x | B18: §2 - TAM by fiscal year ($M, constant FY2026)
B20: Metric | C20: FY2022 | D20: FY2023 | E20: FY2024 | F20: FY2025 | G20: FY2026 | H20: FY2027 | I20: FY22-27
B21: BC base (P-5c Basic Construction) | C21: ='SCN Budget'!C120 | D21: ='SCN Budget'!D120 | E21: ='SCN Budget'!E120 | F21: ='SCN Budget'!F120 | G21: ='SCN Budget'!G120 | H21: ='SCN Budget'!H120 | I21: =SUM(C21:H21)
B22: OBBBA mandatory BC base | C22: ='OBBBA Mandatory'!C37 | D22: ='OBBBA Mandatory'!D37 | E22: ='OBBBA Mandatory'!E37 | F22: ='OBBBA Mandatory'!F37 | G22: ='OBBBA Mandatory'!G37 | H22: ='OBBBA Mandatory'!H37 | I22: =SUM(C22:H22)
B23: AP/LLTM base (P-10 Ship Construction EOQ) | C23: ='SCN Budget'!C128 | D23: ='SCN Budget'!D128 | E23: ='SCN Budget'!E128 | F23: ='SCN Budget'!F128 | G23: ='SCN Budget'!G128 | H23: ='SCN Budget'!H128 | I23: =SUM(C23:H23)
B24: Applied BC coefficient (from Place of Performance) | C24: ='Place of Performance'!E14 | D24: ='Place of Performance'!E13 | E24: ='Place of Performance'!E13 | F24: ='Place of Performance'!E13 | G24: ='Place of Performance'!E13 | H24: ='Place of Performance'!E13
B25: TAM - BC stream | C25: =C21*C$24 | D25: =D21*D$24 | E25: =E21*E$24 | F25: =F21*F$24 | G25: =G21*G$24 | H25: =H21*H$24 | I25: =SUM(C25:H25)
B26: TAM - OBBBA mandatory stream | C26: =C22*C$24 | D26: =D22*D$24 | E26: =E22*E$24 | F26: =F22*F$24 | G26: =G22*G$24 | H26: =H22*H$24 | I26: =SUM(C26:H26)
B27: TAM - AP/LLTM stream | C27: =C23*'Assumptions'!C9 | D27: =D23*'Assumptions'!C9 | E27: =E23*'Assumptions'!C9 | F27: =F23*'Assumptions'!C9 | G27: =G23*'Assumptions'!C9 | H27: =H23*'Assumptions'!C9 | I27: =SUM(C27:H27)
B28: TAM (all streams) | C28: =SUM(C25:C27) | D28: =SUM(D25:D27) | E28: =SUM(E25:E27) | F28: =SUM(F25:F27) | G28: =SUM(G25:G27) | H28: =SUM(H25:H27) | I28: =SUM(C28:H28)
A31: x | B31: §2a - Roll-up & applied coefficient
B33: Measure | C33: Value
B34: Cumulative TAM (FY22-27) $M | C34: =I28
B35: Average annual TAM $M/yr | C35: =C34/6
B36: of which OBBBA mandatory TAM (cumulative) $M | C36: =I26
B37: of which AP/LLTM TAM (cumulative) $M | C37: =I27
B38: Applied BC supplier coefficient | C38: ='Place of Performance'!E13
B39: Applied BC coefficient, FY2022 vintage | C39: ='Place of Performance'!E14
A42: x | B42: §3 - Penetration and outyears ($M)
B44: Metric | C44: FY2022 | D44: FY2023 | E44: FY2024 | F44: FY2025 | G44: FY2026 | H44: FY2027
B45: Outsourced TAM, all streams ($M) | C45: =N(C28) | D45: =N(D28) | E45: =N(E28) | F45: =N(F28) | G45: =N(G28) | H45: =N(H28)
B46: Total ship spend: P-5c Total Ship Estimate ($M) | C46: ='SCN Budget'!C112 | D46: ='SCN Budget'!D112 | E46: ='SCN Budget'!E112 | F46: ='SCN Budget'!F112 | G46: ='SCN Budget'!G112 | H46: ='SCN Budget'!H112
B47: plus OBBBA gross award ($M) | C47: =N('OBBBA Mandatory'!C32) | D47: =N('OBBBA Mandatory'!D32) | E47: =N('OBBBA Mandatory'!E32) | F47: =N('OBBBA Mandatory'!F32) | G47: =N('OBBBA Mandatory'!G32) | H47: =N('OBBBA Mandatory'!H32)
B48: Total ship spend incl. OBBBA ($M) | C48: =C46+N(C47) | D48: =D46+N(D47) | E48: =E46+N(E47) | F48: =F46+N(F47) | G48: =G46+N(G47) | H48: =H46+N(H47)
B49: Penetration: TAM / total ship spend | C49: =IF(C48=0,"",C45/C48) | D49: =IF(D48=0,"",D45/D48) | E49: =IF(E48=0,"",E45/E48) | F49: =IF(F48=0,"",F45/F48) | G49: =IF(G48=0,"",G45/G48) | H49: =IF(H48=0,"",H45/H48)
B51: Measure | C51: Value
B52: FY22-25 average penetration | C52: =SUM(C45:F45)/SUM(C48:F48)
B53: Forecast BC share | C53: =SUM(C21:F21)/SUM(C46:F46)
B54: Outyear BC coefficient, low | C54: ='Place of Performance'!E13
...

Sheet SCN Budget
A2: x | B2: SCN Budget
B3: PB2027 P-5c cost categories and constant-dollar BC bases
A6: x | B6: §1 - Basic Construction by program
B8: Measure | C8: FY2022 | D8: FY2023 | E8: FY2024 | F8: FY2025 | G8: FY2026 | H8: FY2027 | I8: Total
B9: Virginia Basic Construction | C9: ='SCN Budget'!C50 | D9: ='SCN Budget'!D50 | E9: ='SCN Budget'!E50 | F9: ='SCN Budget'!F50 | G9: ='SCN Budget'!G50 | H9: ='SCN Budget'!H50 | I9: =SUM(C9:H9)
B10: Columbia Basic Construction | C10: ='SCN Budget'!C87 | D10: ='SCN Budget'!D87 | E10: ='SCN Budget'!E87 | F10: ='SCN Budget'!F87 | G10: ='SCN Budget'!G87 | H10: ='SCN Budget'!H87 | I10: =SUM(C10:H10)
B11: DDG-51 Basic Construction | C11: ='SCN Budget'!C120 | D11: ='SCN Budget'!D120 | E11: ='SCN Budget'!E120 | F11: ='SCN Budget'!F120 | G11: ='SCN Budget'!G120 | H11: ='SCN Budget'!H120 | I11: =SUM(C11:H11)
B12: Portfolio Basic Construction | C12: =N('SCN Budget'!C50)+N('SCN Budget'!C87)+N('SCN Budget'!C120) | D12: =N('SCN Budget'!D50)+N('SCN Budget'!D87)+N('SCN Budget'!D120) | E12: =N('SCN Budget'!E50)+N('SCN Budget'!E87)+N('SCN Budget'!E120) | F12: =N('SCN Budget'!F50)+N('SCN Budget'!F87)+N('SCN Budget'!F120) | G12: =N('SCN Budget'!G50)+N('SCN Budget'!G87)+N('SCN Budget'!G120) | H12: =N('SCN Budget'!H50)+N('SCN Budget'!H87)+N('SCN Budget'!H120) | I12: =SUM(C12:H12)
B13: Constant-FY2026 factor (then-year x this; from Deflators) | C13: ='Deflators'!D9 | D13: ='Deflators'!D10 | E13: ='Deflators'!D11 | F13: ='Deflators'!D12 | G13: ='Deflators'!D13 | H13: ='Deflators'!D14
A16: x | B16: §2 - Virginia P-5c
B18: Metric | C18: FY2022 | D18: FY2023 | E18: FY2024 | F18: FY2025 | G18: FY2026 | H18: FY2027
B19: Total Ship Estimate | C19: 6915.757 | D19: 7250.579 | E19: 11377.643 | F19: 9500.534 | G19: 5389.109 | H19: 11437.036
B20: Plans Costs | C20: 252.399 | D20: 192.169 | E20: 207.166 | F20: 2595.816 | G20: 219.603 | H20: 223.443
B21: Propulsion Equipment | C21: 1046.83 | D21: 1083.115 | E21: 1121.47 | F21: 1004.95 | G21: 1035.07 | H21: 1273.09
B22: Electronics | C22: 540.536 | D22: 551.346 | E22: 562.372 | F22: 313.264 | G22: 598.515 | H22: 624.898
B23: Hull, Mechanical, Electrical (HM&E) | C23: 139.293 | D23: 141.566 | E23: 144.189 | F23: 98.937 | G23: 150.015 | H23: 153.016
B24: Ordnance
B25: Other Cost | C25: 67.806 | D25: 69.162 | E25: 70.546 | F25: 35.978 | G25: 73.395 | H25: 74.863
B26: Technology Insertion | C26: 15.398 | D26: 15.706 | E26: 16.02 | F26: 16.34 | G26: 16.667 | H26: 17.001
B27: GFE Sum | C27: 1587.366 | D27: 1634.461 | E27: 1683.842 | F27: 1318.214 | G27: 1633.585 | H27: 1897.988
B28: Change Orders | C28: 95.212 | D28: 102.067 | E28: 185.118 | F28: 108.705 | G28: 159.052 | H28: 181.415
B29: Basic Construction (TAM base) | C29: 4758.283 | D29: 5095.448 | E29: 9070.762 | F29: 5326.544 | G29: 3136.792 | H29: 8889.31
A31: x | B31: §2a - Ratios
B33: Ratio | C33: FY2022 | D33: FY2023 | E33: FY2024 | F33: FY2025 | G33: FY2026 | H33: FY2027
B34: BC % of Total | C34: =IF(C19=0,"",C29/C19) | D34: =IF(D19=0,"",D29/D19) | E34: =IF(E19=0,"",E29/E19) | F34: =IF(F19=0,"",F29/F19) | G34: =IF(G19=0,"",G29/G19) | H34: =IF(H19=0,"",H29/H19)
B35: GFE % of Total | C35: =IF(C19=0,"",C27/C19) | D35: =IF(D19=0,"",D27/D19) | E35: =IF(E19=0,"",E27/E19) | F35: =IF(F19=0,"",F27/F19) | G35: =IF(G19=0,"",G27/G19) | H35: =IF(H19=0,"",H27/H19)
A37: x | B37: §2b - Constant FY2026 $M
B39: Metric | C39: FY2022 | D39: FY2023 | E39: FY2024 | F39: FY2025 | G39: FY2026 | H39: FY2027
B40: Total Ship Estimate | C40: =C19*C$13 | D40: =D19*D$13 | E40: =E19*E$13 | F40: =F19*F$13 | G40: =G19*G$13 | H40: =H19*H$13
B41: Plans Costs | C41: =C20*C$13 | D41: =D20*D$13 | E41: =E20*E$13 | F41: =F20*F$13 | G41: =G20*G$13 | H41: =H20*H$13
B42: Propulsion Equipment | C42: =C21*C$13 | D42: =D21*D$13 | E42: =E21*E$13 | F42: =F21*F$13 | G42: =G21*G$13 | H42: =H21*H$13
B43: Electronics | C43: =C22*C$13 | D43: =D22*D$13 | E43: =E22*E$13 | F43: =F22*F$13 | G43: =G22*G$13 | H43: =H22*H$13
B44: Hull, Mechanical, Electrical (HM&E) | C44: =C23*C$13 | D44: =D23*D$13 | E44: =E23*E$13 | F44: =F23*F$13 | G44: =G23*G$13 | H44: =H23*H$13
B45: Ordnance | C45: =C24*C$13 | D45: =D24*D$13 | E45: =E24*E$13 | F45: =F24*F$13 | G45: =G24*G$13 | H45: =H24*H$13
B46: Other Cost | C46: =C25*C$13 | D46: =D25*D$13 | E46: =E25*E$13 | F46: =F25*F$13 | G46: =G25*G$13 | H46: =H25*H$13
B47: Technology Insertion | C47: =C26*C$13 | D47: =D26*D$13 | E47: =E26*E$13 | F47: =F26*F$13 | G47: =G26*G$13 | H47: =H26*H$13
B48: GFE Sum | C48: =C27*C$13 | D48: =D27*D$13 | E48: =E27*E$13 | F48: =F27*F$13 | G48: =G27*G$13 | H48: =H27*H$13
B49: Change Orders | C49: =C28*C$13 | D49: =D28*D$13 | E49: =E28*E$13 | F49: =F28*F$13 | G49: =G28*G$13 | H49: =H28*H$13
B50: Basic Construction (TAM base) | C50: =C29*C$13 | D50: =D29*D$13 | E50: =E29*E$13 | F50: =F29*F$13 | G50: =G29*G$13 | H50: =H29*H$13
A53: x | B53: §3 - Columbia P-5c
...

Sheet Place of Performance
A2: x | B2: Place of Performance
B3: Award place of performance and supplier coefficients
A6: x | B6: §1 - Supplier coefficients
A8: x | B8: §1a - Applied coefficients
B10: Basis | C10: Eligible $M | D10: Supplier $M | E10: Coefficient
B11: Virginia BC | C11: =SUMPRODUCT(('Place of Performance'!B26:B76="Virginia")*('Place of Performance'!G26:G76="BC")*'Place of Performance'!J26:J76) | D11: =SUMPRODUCT(('Place of Performance'!B26:B76="Virginia")*('Place of Performance'!G26:G76="BC")*'Place of Performance'!J26:J76*('Place of Performance'!M26:M76+'Place of Performance'!N26:N76)) | E11: =IF(C11=0,"",D11/C11)
B12: Columbia BC | C12: =SUMPRODUCT(('Place of Performance'!B26:B76="Columbia")*('Place of Performance'!G26:G76="BC")*'Place of Performance'!J26:J76) | D12: =SUMPRODUCT(('Place of Performance'!B26:B76="Columbia")*('Place of Performance'!G26:G76="BC")*'Place of Performance'!J26:J76*('Place of Performance'!M26:M76+'Place of Performance'!N26:N76)) | E12: =IF(C12=0,"",D12/C12)
B13: DDG-51 BC, FY23-27 | C13: =SUMPRODUCT(('Place of Performance'!B26:B76="DDG-51")*('Place of Performance'!G26:G76="BC")*('Place of Performance'!I26:I76=0)*'Place of Performance'!J26:J76) | D13: =SUMPRODUCT(('Place of Performance'!B26:B76="DDG-51")*('Place of Performance'!G26:G76="BC")*('Place of Performance'!I26:I76=0)*'Place of Performance'!J26:J76*('Place of Performance'!M26:M76+'Place of Performance'!N26:N76)) | E13: =IF(C13=0,"",D13/C13)
B14: DDG-51 BC, FY2022 | C14: =SUMPRODUCT(('Place of Performance'!B26:B76="DDG-51")*('Place of Performance'!G26:G76="BC")*('Place of Performance'!I26:I76=1)*'Place of Performance'!J26:J76) | D14: =SUMPRODUCT(('Place of Performance'!B26:B76="DDG-51")*('Place of Performance'!G26:G76="BC")*('Place of Performance'!I26:I76=1)*'Place of Performance'!J26:J76*('Place of Performance'!M26:M76+'Place of Performance'!N26:N76)) | E14: =IF(C14=0,"",D14/C14)
A16: x | B16: §1b - Reference coefficients
B18: Basis | C18: Eligible $M | D18: Supplier $M | E18: Coefficient
B19: DDG-51 disclosed | C19: =SUMPRODUCT(('Place of Performance'!B26:B76="DDG-51")*('Place of Performance'!G26:G76="BC")*('Place of Performance'!I26:I76=0)*('Place of Performance'!H26:H76=0)*'Place of Performance'!J26:J76) | D19: =SUMPRODUCT(('Place of Performance'!B26:B76="DDG-51")*('Place of Performance'!G26:G76="BC")*('Place of Performance'!I26:I76=0)*('Place of Performance'!H26:H76=0)*'Place of Performance'!J26:J76*('Place of Performance'!M26:M76+'Place of Performance'!N26:N76)) | E19: =IF(C19=0,"",D19/C19)
B20: Submarine AP/LLTM | C20: =SUMPRODUCT((('Place of Performance'!B26:B76="Virginia")+('Place of Performance'!B26:B76="Columbia"))*('Place of Performance'!G26:G76="AP_LLTM")*'Place of Performance'!J26:J76) | D20: =SUMPRODUCT((('Place of Performance'!B26:B76="Virginia")+('Place of Performance'!B26:B76="Columbia"))*('Place of Performance'!G26:G76="AP_LLTM")*'Place of Performance'!J26:J76*('Place of Performance'!M26:M76+'Place of Performance'!N26:N76)) | E20: =IF(C20=0,"",D20/C20)
A23: x | B23: §2 - Award corpus
B25: Program | C25: Date | D25: PIID | E25: Prime | F25: Work Type | G25: Stream | H25: Master | I25: FY18-22 vintage | J25: $M | K25: Prime % | L25: Co-prime % | M25: Other US % | N25: Foreign % | O25: Source
B26: Virginia | C26: 2019-12-02 | D26: N00024-17-C-2100 | E26: General Dynamics Electric Boat | F26: construction | G26: BC | H26: 1 | I26: 0 | J26: 22209.893 | K26: 0.41 | L26: 0.25 | M26: 0.33 | N26: 0.01 | O26: DoD Contracts 2019-12-02 (defense.gov Article 2030017); Block V, 9 boats FY19-23
B27: Virginia | C27: 2025-04-30 | D27: - | E27: - | F27: lltm_early_mfg | G27: AP_LLTM | H27: 0 | I27: 0 | J27: 12418.145 | K27: 0.4 | L27: 0.32 | M27: 0.28 | N27: 0 | O27: https://www.globalsecurity.org/military/library/news/2025/04/dod-contracts_4170827.htm
B28: Virginia | C28: 2026-05-11 | D28: N00024-24-C-2110 | E28: General Dynamics Electric Boat Corp. | F28: lltm_early_mfg | G28: AP_LLTM | H28: 0 | I28: 0 | J28: 2305.53 | K28: 0 | L28: 0.02 | M28: 0.98 | N28: 0 | O28: https://www.globalsecurity.org/military/library/news/2026/05/dod-contracts_4479470.htm
B29: Virginia | C29: 2025-06-26 | D29: N00024-24-C-2110 | E29: - | F29: lltm_early_mfg | G29: AP_LLTM | H29: 0 | I29: 0 | J29: 1851.065 | K29: 0 | L29: 0 | M29: 1 | N29: 0 | O29: https://www.globalsecurity.org/military/library/news/2025/06/dod-contracts_4227676.htm
B30: Virginia | C30: 2025-03-25 | D30: N00024-24-C-2110 | E30: - | F30: lltm_early_mfg | G30: AP_LLTM | H30: 0 | I30: 0 | J30: 1065.31 | K30: 0 | L30: 0 | M30: 1 | N30: 0 | O30: https://www.globalsecurity.org/military/library/news/2025/03/dod-contracts_4134550.htm
B31: Virginia | C31: 2023-10-13 | D31: N00024-24-C-2110 | E31: General Dynamics Electric Boat Corp. | F31: lltm_early_mfg | G31: AP_LLTM | H31: 0 | I31: 0 | J31: 216.51 | K31: 0 | L31: 0 | M31: 1 | N31: 0 | O31: https://www.defense.gov/News/Contracts/Contract/Article/3557261/ (via web.archive.org)
B32: Virginia | C32: 2025-01-08 | D32: - | E32: - | F32: construction | G32: BC | H32: 0 | I32: 0 | J32: 188 | K32: 0 | L32: 0.02 | M32: 0.98 | N32: 0 | O32: https://www.globalsecurity.org/military/library/news/2025/01/dod-contracts_4024737.htm
B33: Virginia | C33: 2025-07-21 | D33: N00024-17-C-2100 | E33: General Dynamics Electric Boat Corp. | F33: component_procurement | G33: BC | H33: 0 | I33: 0 | J33: 159.67574 | K33: 0 | L33: 0 | M33: 0 | N33: 0 | O33: https://www.globalsecurity.org/military/library/news/2025/07/dod-contracts_4250988.htm
B34: Virginia | C34: 2024-02-23 | D34: - | E34: General Dynamics Electric Boat Corp. | F34: lltm_early_mfg | G34: AP_LLTM | H34: 0 | I34: 0 | J34: 150.984 | K34: 0 | L34: 0 | M34: 1 | N34: 0 | O34: https://www.defense.gov/News/Contracts/Contract/Article/3685947/ (via web.archive.org)
B35: Virginia | C35: 2024-01-22 | D35: N00024-17-C-2100 | E35: General Dynamics Electric Boat Corp. | F35: lltm_early_mfg | G35: AP_LLTM | H35: 0 | I35: 0 | J35: 96.437891 | K35: 0 | L35: 0 | M35: 1 | N35: 0 | O35: https://www.defense.gov/News/Contracts/Contract/Article/3652144/ (via web.archive.org)
B36: Virginia | C36: 2025-08-11 | D36: - | E36: - | F36: component_procurement | G36: BC | H36: 0 | I36: 0 | J36: 86 | K36: 0 | L36: 0 | M36: 0 | N36: 0 | O36: https://www.globalsecurity.org/military/library/news/2025/08/dod-contracts_4271589.htm
B37: Virginia | C37: 2025-07-29 | D37: - | E37: CIRCOR Naval Solutions LLC | F37: component_procurement | G37: BC | H37: 0 | I37: 0 | J37: 40 | K37: 0 | L37: 0 | M37: 0 | N37: 0 | O37: https://www.globalsecurity.org/military/library/news/2025/07/dod-contracts_4258695.htm
... B76: DDG-51 | C76: 2018-09-27 | D76: N00024-18-C-2307 | E76: Huntington Ingalls Industries | F76: construction | G76: BC | H76: 1 | I76: 1 | J76: 5104.669 | K76: 0 | L76: 0.91 | M76: 0.09 | N76: 0 | O76: DoD Contracts 2018-09-27 (defense.gov Article 1647166); FY18-22 MYP

Sheet OBBBA Mandatory
A2: x | B2: OBBBA Mandatory
B3: FY2026 mandatory awards and BC/GFE bridge
A6: x | B6: §1 - Mandatory awards
B8: Award | C8: Section | D8: Gross $M
B9: Virginia (LI 2013) | C9: 20002(16) | D9: 4600
B10: DDG-51 (LI 2122) | C10: 20002(17) | D10: 5400
A13: x | B13: §2 - Virginia bridge ($M)
B15: Metric | C15: FY2022 | D15: FY2023 | E15: FY2024 | F15: FY2025 | G15: FY2026 | H15: FY2027
B16: Sec. 20002(16) award, then-year $M | C16: 0 | D16: 0 | E16: 0 | F16: 0 | G16: 4600 | H16: 0
B17: Gross award, constant FY2026 $M | C17: =C16*'Deflators'!D9 | D17: =D16*'Deflators'!D10 | E17: =E16*'Deflators'!D11 | F17: =F16*'Deflators'!D12 | G17: =G16*'Deflators'!D13 | H17: =H16*'Deflators'!D14
B18: Gross award, execution-aligned, constant FY2026 $M | C18: 0 | D18: 0 | E18: 0 | F18: 0 | G18: =G16*(1-'Assumptions'!C18)*'Deflators'!D13 | H18: =G16*'Assumptions'!C18*'Deflators'!D14
A20: x | B20: §2a - BC/GFE split
B22: Metric | C22: FY2022 | D22: FY2023 | E22: FY2024 | F22: FY2025 | G22: FY2026 | H22: FY2027
B23: OBBBA BC base, then-year $M | C23: =C16*'Assumptions'!E15 | D23: =D16*'Assumptions'!E15 | E23: =E16*'Assumptions'!E15 | F23: =F16*'Assumptions'!E15 | G23: =G16*'Assumptions'!E15*(1-'Assumptions'!C18) | H23: =H16*'Assumptions'!E15+G16*'Assumptions'!E15*'Assumptions'!C18
B24: OBBBA BC base, constant FY2026 $M | C24: =C23*'Deflators'!D9 | D24: =D23*'Deflators'!D10 | E24: =E23*'Deflators'!D11 | F24: =F23*'Deflators'!D12 | G24: =G23*'Deflators'!D13 | H24: =H23*'Deflators'!D14
B25: GFE / non-BC remainder ($M; excluded from TAM) | C25: =C17-C24 | D25: =D17-D24 | E25: =E17-E24 | F25: =F17-F24 | G25: =G17-G24 | H25: =H17-H24
A28: x | B28: §3 - DDG-51 bridge ($M)
B30: Metric | C30: FY2022 | D30: FY2023 | E30: FY2024 | F30: FY2025 | G30: FY2026 | H30: FY2027
B31: Sec. 20002(17) award, then-year $M | C31: 0 | D31: 0 | E31: 0 | F31: 0 | G31: 5400 | H31: 0
B32: Gross award, constant FY2026 $M | C32: =C31*'Deflators'!D9 | D32: =D31*'Deflators'!D10 | E32: =E31*'Deflators'!D11 | F32: =F31*'Deflators'!D12 | G32: =G31*'Deflators'!D13 | H32: =H31*'Deflators'!D14
A34: x | B34: §3a - BC/GFE split
B36: Metric | C36: FY2022 | D36: FY2023 | E36: FY2024 | F36: FY2025 | G36: FY2026 | H36: FY2027
B37: OBBBA BC base, constant FY2026 $M | C37: =C32*'Assumptions'!E16 | D37: =D32*'Assumptions'!E16 | E37: =E32*'Assumptions'!E16 | F37: =F32*'Assumptions'!E16 | G37: =G32*'Assumptions'!E16 | H37: =H32*'Assumptions'!E16
B38: GFE / non-BC remainder ($M; excluded from TAM) | C38: =C32-C37 | D38: =D32-D37 | E38: =E32-E37 | F38: =F32-F37 | G38: =G32-G37 | H38: =H32-H37

Sheet FYDP Outyears
A2: x | B2: FYDP Outyears
B3: PB2027 P-40 gross spend, FY2025-31
A6: x | B6: §1 - PB2027 P-40 Resource Summary (then-year $M)
B8: Field | C8: Value
B9: Exhibit | C9: PB2027 Navy P-40 (1611N SCN)
B10: Period | C10: FY2025-31; FY2027 = Total (Base+OOC), FY2028-31 = outyears
A13: x | B13: §2 - Virginia (LI 2013), then-year $M
B15: Metric | C15: FY2025 | D15: FY2026 | E15: FY2027 | F15: FY2028 | G15: FY2029 | H15: FY2030 | I15: FY2031
B16: Gross / Weapon System Cost, then-year $M | C16: 9500.534 | D16: 5389.109 | E16: 11437.036 | F16: 11284.824 | G16: 11098.426 | H16: 10196.613 | I16: 10594.23
B17: Procurement quantity (ships) | C17: 1 | D17: 1 | E17: 2 | F17: 2 | G17: 2 | H17: 2 | I17: 2
B18: Net Procurement (P-1), then-year $M (memo) | C18: 7356.904 | D18: 2740.305 | E18: 8402.316 | F18: 8149.065 | G18: 7876.466 | H18: 7283.37 | I18: 7423.079
B19: Total Obligation Authority, then-year $M (memo) | C19: 13320.211 | D19: 6377.536 | E19: 13151.309 | F19: 13011.118 | G19: 14686.814 | H19: 12268.711 | I19: 12016.801
A21: x | B21: §3 - Columbia (LI 1045), then-year $M
B23: Metric | C23: FY2025 | D23: FY2026 | E23: FY2027 | F23: FY2028 | G23: FY2029 | H23: FY2030 | I23: FY2031
B24: Gross / Weapon System Cost, then-year $M | C24: 0 | D24: 10744.317 | E24: 10486.369 | F24: 10137.078 | G24: 10360.998 | H24: 10441.001 | I24: 10693.082
B25: Procurement quantity (ships) | D25: 1 | E25: 1 | F25: 1 | G25: 1 | H25: 1 | I25: 1
B26: Net Procurement (P-1), then-year $M (memo) | C26: 0 | D26: 3928.828 | E26: 6904.785 | F26: 6379.022 | G26: 6057.819 | H26: 6011.645 | I26: 6303.401
B27: Total Obligation Authority, then-year $M (memo) | C27: 9580.774 | D27: 9279.594 | E27: 15583.102 | F27: 12834.863 | G27: 11351.481 | H27: 12359.708 | I27: 12020.144
A29: x | B29: §4 - DDG-51 (LI 2122), then-year $M
B31: Metric | C31: FY2025 | D31: FY2026 | E31: FY2027 | F31: FY2028 | G31: FY2029 | H31: FY2030 | I31: FY2031
B32: Gross / Weapon System Cost, then-year $M | C32: 7858.814 | D32: 306.125 | E32: 4256.914 | F32: 4026.201 | G32: 4209.44 | H32: 6613.151 | I32: 6964.218
B33: Procurement quantity (ships) | C33: 3 | E33: 1 | F33: 1 | G33: 1 | H33: 2 | I33: 2
B34: Net Procurement (P-1), then-year $M (memo) | C34: 6268.519 | D34: 10.773 | E34: 2954.238 | F34: 4026.201 | G34: 3707.169 | H34: 6110.88 | I34: 6461.913
B35: Total Obligation Authority, then-year $M (memo) | C35: 8268.628 | D35: 1942.268 | E35: 3132.462 | F35: 6124.325 | G35: 3993.544 | H35: 6375.629 | I35: 6565.705
A38: x | B38: §5 - Constant FY2026 $M
B40: Class | C40: FY2025 | D40: FY2026 | E40: FY2027 | F40: FY2028 | G40: FY2029 | H40: FY2030 | I40: FY2031
B41: Constant-FY2026 factor (then-year x this; from Deflators) | C41: ='Deflators'!D12 | D41: ='Deflators'!D13 | E41: ='Deflators'!D14 | F41: ='Deflators'!D15 | G41: ='Deflators'!D16 | H41: ='Deflators'!D17 | I41: ='Deflators'!D18
B42: Virginia (LI 2013) | C42: =C16*C$41 | D42: =D16*D$41 | E42: =E16*E$41 | F42: =F16*F$41 | G42: =G16*G$41 | H42: =H16*H$41 | I42: =I16*I$41
B43: Columbia (LI 1045) | C43: =C24*C$41 | D43: =D24*D$41 | E43: =E24*E$41 | F43: =F24*F$41 | G43: =G24*G$41 | H43: =H24*H$41 | I43: =I24*I$41
B44: DDG-51 (LI 2122) | C44: =C32*C$41 | D44: =D32*D$41 | E44: =E32*E$41 | F44: =F32*F$41 | G44: =G32*G$41 | H44: =H32*H$41 | I44: =I32*I$41
B45: Submarine portfolio (Va + Col), constant FY2026 $M | C45: =N(C42)+N(C43) | D45: =N(D42)+N(D43) | E45: =N(E42)+N(E43) | F45: =N(F42)+N(F43) | G45: =N(G42)+N(G43) | H45: =N(H42)+N(H43) | I45: =N(I42)+N(I43)

Sheet Deflators
A2: x | B2: Deflators
B3: Procurement deflators rebased to FY2026
A6: x | B6: §1 - Procurement deflators
B8: FY | C8: Procurement deflator (FY2025=100) | D8: Factor to constant FY2026 $ | E8: Basis
B9: FY2022 | C9: 93.13 | D9: 1.1 | E9: Green Book Table 5-4
B10: FY2023 | C10: 95.77 | D10: 1.07 | E10: Green Book Table 5-4
B11: FY2024 | C11: 97.92 | D11: 1.04 | E11: Green Book Table 5-4
B12: FY2025 | C12: 100 | D12: 1.02 | E12: Green Book Table 5-4
B13: FY2026 | C13: 102.1 | D13: 1 | E13: Green Book Table 5-4
B14: FY2027 | C14: 104.24 | D14: 0.98 | E14: Green Book Table 5-4
B15: FY2028 | C15: 106.43 | D15: 0.96 | E15: Green Book Table 5-4
B16: FY2029 | C16: 108.67 | D16: 0.94 | E16: Green Book Table 5-4
B17: FY2030 | C17: 110.95 | D17: 0.92 | E17: Extrapolated @ 2.1%/yr
B18: FY2031 | C18: 113.28 | D18: 0.9 | E18: Extrapolated @ 2.1%/yr
A21: x | B21: §2 - Source
B23: Series | C23: Source
B24: Procurement TOA | C24: OSD National Defense Budget Estimates for FY2025 (Green Book), Table 5-4 Procurement TOA, FY2025=100; rebased to FY2026=1.000
B25: FY2030-31 | C25: Extrapolated at 2.1%/yr (Green Book Table 5-3 steady-state purchases inflation)

Sheet Checks
A2: x | B2: Checks
B3: Input bounds, outyear ordering, and completeness
A6: x | B6: §1 - Share bounds
B8: Check | C8: Value | D8: Status
B9: Virginia applied BC coefficient | C9: ='Virginia TAM'!C34 | D9: =IF(AND(C9>0,C9<=1),"OK","FAIL")
B10: Columbia applied BC coefficient | C10: ='Columbia TAM'!C30 | D10: =IF(AND(C10>0,C10<=1),"OK","FAIL")
B11: DDG-51 applied BC coefficient | C11: ='DDG-51 TAM'!C38 | D11: =IF(AND(C11>0,C11<=1),"OK","FAIL")
B12: Virginia OBBBA modeled BC share | C12: ='Assumptions'!E15 | D12: =IF(AND(C12>=0,C12<=1),"OK","FAIL")
B13: DDG-51 OBBBA modeled BC share | C13: ='Assumptions'!E16 | D13: =IF(AND(C13>=0,C13<=1),"OK","FAIL")
B14: DDG-51 AP/LLTM supplier coefficient | C14: ='Assumptions'!C9 | D14: =IF(AND(C14>=0,C14<=1),"OK","FAIL")
A17: x | B17: §2 - Outyear band
B19: Check | C19: Min margin $M | D19: Status
B20: Virginia outyear high >= low | C20: =MIN('Virginia TAM'!C57-'Virginia TAM'!C56,'Virginia TAM'!D57-'Virginia TAM'!D56,'Virginia TAM'!E57-'Virginia TAM'!E56,'Virginia TAM'!F57-'Virginia TAM'!F56) | D20: =IF(C20>=-0.001,"OK","FAIL")
B21: Columbia outyear high >= low | C21: =MIN('Columbia TAM'!C52-'Columbia TAM'!C51,'Columbia TAM'!D52-'Columbia TAM'!D51,'Columbia TAM'!E52-'Columbia TAM'!E51,'Columbia TAM'!F52-'Columbia TAM'!F51) | D21: =IF(C21>=-0.001,"OK","FAIL")
B22: DDG-51 outyear high >= low | C22: =MIN('DDG-51 TAM'!C63-'DDG-51 TAM'!C62,'DDG-51 TAM'!D63-'DDG-51 TAM'!D62,'DDG-51 TAM'!E63-'DDG-51 TAM'!E62,'DDG-51 TAM'!F63-'DDG-51 TAM'!F62) | D22: =IF(C22>=-0.001,"OK","FAIL")
A25: x | B25: §3 - Completeness
B27: Check | C27: Count | D27: Status
B28: Key behavioral knobs present & numeric | C28: =COUNT('Assumptions'!C9,'Assumptions'!C18,'Assumptions'!C26,'Assumptions'!C27,'Assumptions'!E15,'Assumptions'!E16) | D28: =IF(C28=6,"OK","FAIL")
A31: x | B31: §4 - Master check
B33: All checks | C33: =COUNTIF(D9:D28,"FAIL") | D33: =IF(C33=0,"OK","CHECK FAILED")
