Workbook
Name portfolio_tam_annual: 'TAM Build'!$C$143
Name portfolio_tam_cumulative: 'TAM Build'!$C$141
Name portfolio_tam: 'TAM Build'!$C$141
Name broad_sam_annual: 'SAM Build'!$C$120
Name broad_sam_cumulative: 'SAM Build'!$D$120
Name sam_broad: 'SAM Build'!$D$120
Name fiscal_year_count: 'TAM Build'!$C$142
Name bc_supplier_coeff_va: 'TAM Build'!$C$62
Name bc_supplier_coeff_col: 'TAM Build'!$C$63
Name ap_lltm_supplier_coeff: 'TAM Build'!$C$65

Sheet Executive Summary
B2: Executive Summary
A4: x | B4: §1 - Key takeaways
B6: Metric | C6: Value | D6: Source
B7: Average annual portfolio TAM $M | C7: ='TAM Build'!C143 | D7: TAM Build
B8: FY22-FY27 cumulative portfolio TAM $M | C8: ='TAM Build'!C141 | D8: TAM Build
B9: incl. OBBBA mandatory TAM $M (Sec. 20002(16), 1 boat) | C9: ='TAM Build'!C146 | D9: TAM Build
B10: Average annual broad SAM $M | C10: ='SAM Build'!C120 | D10: SAM Build
B11: FY22-FY27 cumulative broad SAM $M | C11: ='SAM Build'!D120 | D11: SAM Build
B12: Virginia BC coefficient (Block V announced POP) | C12: ='TAM Build'!C62 | D12: TAM Build
B13: Columbia BC coefficient (Build I announced POP) | C13: ='TAM Build'!C63 | D13: TAM Build
B14: AP/LLTM additive base $M | C14: ='AP Bridge'!C66 | D14: AP Bridge
B15: Outsourced BC penetration, FY22-27 | C15: ='Outlook'!C36 | D15: Outlook
B16: Implied outyear Outsourced BC, low $M/yr | C16: ='Outlook'!C60 | D16: Outlook
B17: Implied outyear Outsourced BC, high $M/yr | C17: ='Outlook'!C61 | D17: Outlook
B18: FY22-25 average annual TAM $M/yr | C18: ='Outlook'!C69 | D18: Outlook
A21: x | B21: §2 - TAM bridge
A23: x | B23: §2a - BC stream
B25: Step | C25: $M / % | D25: Source
B26: BC construction base (FY22-27) | C26: ='TAM Build'!C144 | D26: TAM Build
B27: x Virginia BC coefficient (Block V announced POP) | C27: ='TAM Build'!C62 | D27: TAM Build
B28: x Columbia BC coefficient (Build I announced POP) | C28: ='TAM Build'!C63 | D28: TAM Build
B29: BC-stream supplier TAM (per-class coeff x per-class base) | C29: =N('TAM Build'!C132)+N('TAM Build'!D132)+N('TAM Build'!E132)+N('TAM Build'!F132)+N('TAM Build'!G132)+N('TAM Build'!H132) | D29: TAM Build
A31: x | B31: §2b - AP/LLTM stream
B33: Step | C33: $M / % | D33: Source
B34: P-10 gross AP top-line | C34: ='AP Bridge'!C62 | D34: AP Bridge
B35: less GFE / design / weapons | C35: ='AP Bridge'!C63 | D35: AP Bridge
B36: less already inside P-5c BC | C36: ='AP Bridge'!C64 | D36: AP Bridge
B37: less un-itemized overlap | C37: ='AP Bridge'!C65 | D37: AP Bridge
B38: AP/LLTM additive base | C38: ='AP Bridge'!C66 | D38: AP Bridge
B39: AP/LLTM reference coefficient | C39: ='TAM Build'!C65 | D39: TAM Build
B40: AP/LLTM-stream supplier TAM | C40: =N('TAM Build'!C133)+N('TAM Build'!D133)+N('TAM Build'!E133)+N('TAM Build'!F133)+N('TAM Build'!G133)+N('TAM Build'!H133) | D40: TAM Build
A42: x | B42: §2c - OBBBA mandatory (Sec. 20002(16))
B44: Step | C44: $M / % | D44: Source
B45: Gross award (Sec. 20002(16), 2nd FY26 Virginia boat) | C45: ='OBBBA Mandatory'!I28 | D45: OBBBA Mandatory
B46: OBBBA BC share of award | C46: ='Assumptions'!E49 | D46: Assumptions
B47: OBBBA mandatory BC base (FY22-27) | C47: ='TAM Build'!C145 | D47: TAM Build
B48: x Virginia BC coefficient (the OBBBA boat is a Virginia) | C48: ='TAM Build'!C62 | D48: TAM Build
B49: OBBBA mandatory supplier TAM | C49: ='TAM Build'!C146 | D49: TAM Build
B50: FY2027 execution spillover assumption | C50: ='Assumptions'!C46 | D50: Assumptions
A52: x | B52: §2d - Portfolio TAM
...

Sheet Methodology
B2: Methodology
A4: x | B4: §1 - Definitions
B6: Term | C6: Definition | D6: Treatment
B7: TAM | C7: non-GFE/SIB new-construction supplier opportunity | D7: BC base x coeff + AP/LLTM base x coeff
B8: SAM | C8: portion of TAM in targeted work-type buckets | D8: scenario menu
B9: BC | C9: Basic Construction (P-5c, GFE-free) | D9: the headline TAM stream
B10: AP/LLTM | C10: advance procurement / long-lead material | D10: reference stream; additive base = 0
B11: OBBBA mandatory | C11: Sec. 20002 mandatory new-construction funding | D11: gross x BC share x BC coeff; FY26 BA (spillover lever to FY27)
B12: GFE | C12: government-furnished equipment / weapons | D12: excluded from TAM
B13: SIB | C13: submarine industrial base / capacity grants | D13: excluded from SAM
B14: POP | C14: place of performance | D14: drives the supplier coefficient
B15: Supplier coefficient | C15: $-weighted supplier+foreign POP share | D15: applied to each stream base
B16: Worktype share gate | C16: per-class bucket shares measured on GDEB-PIID subawards, FY2022-25 window | D16: non-GDEB prime records excluded
B17: Distributed-production view | C17: work away from the final-assembly yard | D17: appendix context only
A20: x | B20: §2 - Formula framework
A22: x | B22: §2a - TAM framework
B24: TAM = BC base x class-vintage BC supplier coefficient + AP/LLTM base x AP/LLTM supplier coefficient
B25: Applied: per-class BC base x its funding construction master's announced-POP coefficient + $0 AP/LLTM base x AP/LLTM reference coeff
B26: Coefficient (live) | C26: Value
B27: Virginia BC coefficient (Block V announced POP) | C27: ='TAM Build'!C62
B28: Columbia BC coefficient (Build I announced POP) | C28: ='TAM Build'!C63
B29: AP/LLTM reference coefficient | C29: ='TAM Build'!C65
B31: §2b - SAM framework
B33: SAM scenario = SUMPRODUCT(bucket TAM, scenario inclusion flag)
B34: Bucket shares are per-class per-FY vectors measured on gated evidence: GDEB construction/LLTM PIIDs only (BPMI / LM / BAE / RR prime records excluded), Virginia and Columbia separately, FY2022-FY2025 reporting years -> Worktype by FY.
B35: Each class's annual TAM is allocated at its own FY's vector; FY2026-27 use the FY22-25 window vector (no usable subaward reporting yet).
A37: x | B37: §2c - Penetration & outyear outlook
B39: Penetration = Outsourced BC TAM (all streams) / total ship spend (Va + Col Total Ship Estimate + OBBBA gross), constant FY2026 $, measured per class.
B40: Window averages are ratios of sums; implied FY28-31 Outsourced BC = each class's PB2027 FYDP gross x its penetration assumption, low = class FY22-25 average, high = low x (1 + stated outsourcing-intent uplift, Assumptions §9); portfolio = Virginia + Columbia.
B41: FYDP outyears are the PB2027 request, not appropriation; FY2030-FY2031 deflators are extrapolated (Deflators tab).
A44: x | B44: §2d - Evidence basis by fiscal year
B46: FY | C46: Dollar basis | D46: Outsourced % basis
B47: 2022-2025 | C47: Settled actuals (PB >= FY+2 vintage rule) | D47: Class-vintage announced POP of the funding construction masters: Virginia 34% (Block V, 2019-12-02 bulletin), Columbia 22% (Build I, 2020-11-05 bulletin)
B48: 2026 | C48: Enacted: PB2027 P-5c + OBBBA PL 119-21 Sec. 20002(16) mandatory | D48: Same class coefficients (OBBBA boat is a Virginia -> 34%); the OBBBA BC share (observed Virginia FY26 P-5c ratio, ~58.2%) is the one assumption layer
B49: 2027 | C49: PB2027 request - not yet appropriated | D49: Same class coefficients; OBBBA FY27 execution spillover defaults to 0 - estimate until appropriation
B50: 2028-2031 | C50: PB2027 FYDP request (Outlook only; outside TAM) | D50: Penetration assumption, not announcement POP - styled as an estimate
B51: Announced POP is the contract-level planned distribution ('Work will be performed in...'), not realized per-FY actuals.
B52: The pooled 2022-2026 corpus coefficient (35.0%) is retained on TAM Build §3a as a reference; Block VI construction is unawarded, so the Virginia row restates on its announcement.
B53: The AP/LLTM additive base is 0 (P-10 supplier LLTM already sits inside P-5c BC); no AP coefficient is applied.
A56: x | B56: §3 - Market-sizing flow
...

Sheet Assumptions
B2: Assumptions
A4: x | B4: §1 - Run settings
B6: Setting | C6: Value
B7: Program | C7: Submarine
B8: FY range start | C8: 2022
B9: FY range end | C9: 2027
B10: Units | C10: Constant FY2026 $M (then-year source retained)
B11: Default SAM scenario | C11: Broad component mfg
A14: x | B14: §2 - Stream controls
B16: Control | C16: Value
B17: Include BC stream | C17: 1
B18: Include AP/LLTM stream | C18: 1
B19: Include OBBBA mandatory (Sec. 20002(16)) stream | C19: 1
B20: Prior-year AP credit treatment | C20: none (credits = 0)
A23: x | B23: §3 - AP/LLTM additive base ($M, confirmed 0)
B25: Class | C25: 2022 | D25: 2023 | E25: 2024 | F25: 2025 | G25: 2026 | H25: 2027
B26: Virginia (LI 2013) | C26: 0 | D26: 0 | E26: 0 | F26: 0 | G26: 0 | H26: 0
B27: Columbia (LI 1045) | C27: 0 | D27: 0 | E27: 0 | F27: 0 | G27: 0 | H27: 0
B28: Total (Va + Col) | C28: =N(C26)+N(C27) | D28: =N(D26)+N(D27) | E28: =N(E26)+N(E27) | F28: =N(F26)+N(F27) | G28: =N(G26)+N(G27) | H28: =N(H26)+N(H27)
A30: x | B30: §3b - Constant FY2026 $M (then-year x deflator)
B32: Class | C32: 2022 | D32: 2023 | E32: 2024 | F32: 2025 | G32: 2026 | H32: 2027
B33: Virginia (LI 2013) | C33: =C26*'Deflators'!D7 | D33: =D26*'Deflators'!D8 | E33: =E26*'Deflators'!D9 | F33: =F26*'Deflators'!D10 | G33: =G26*'Deflators'!D11 | H33: =H26*'Deflators'!D12
B34: Columbia (LI 1045) | C34: =C27*'Deflators'!D7 | D34: =D27*'Deflators'!D8 | E34: =E27*'Deflators'!D9 | F34: =F27*'Deflators'!D10 | G34: =G27*'Deflators'!D11 | H34: =H27*'Deflators'!D12
A36: x | B36: §3a - P-10 gross AP reference ($M, overlaps BC)
B38: Class | C38: 2022 | D38: 2023 | E38: 2024 | F38: 2025 | G38: 2026 | H38: 2027
B39: Virginia (LI 2013) | C39: 2105.407 | D39: 2025.651 | E39: 3358.782 | F39: 3720.303 | G39: 3126.816 | H39: 4143.618
B40: Columbia (LI 1045) | C40: 1773.98 | D40: 2778.553 | E40: 5345.734 | F40: 6215.939 | G40: 5350.766 | H40: 4763.342
A43: x | B43: §4 - OBBBA mandatory controls (Sec. 20002(16))
B45: Control | C45: Value
B46: FY2027 execution spillover (share of FY26 award) | C46: 0
B48: Measure | C48: Observed | D48: Adjustment | E48: Modeled
B49: OBBBA BC share of award (Virginia FY26 P-5c) | C49: ='SCN Budget'!G38 | D49: 0 | E49: =C49+D49
A52: x | B52: §5 - Construction-master announced POP (class-vintage BC coefficients)
B54: Master | C54: PIID | D54: $M | E54: EB % | F54: HII % | G54: Other-US % | H54: Foreign %
B55: Virginia Block V (FY19-23 boats) | C55: N00024-17-C-2100 | D55: 22209.893 | E55: 0.41 | F55: 0.25 | G55: 0.33 | H55: 0.01
B56: Columbia Build I (SSBN 826 + 827) | C56: N00024-17-C-2117 | D56: 9473.511 | E56: 0.53 | F56: 0.25 | G56: 0.22 | H56: 0
A59: x | B59: §6 - Scenario selector
B61: Selected scenario | C61: Cumulative SAM $M | D61: % of TAM | E61: Avg annual SAM $M
B62: =C11 | C62: ='SAM Build'!D126 | D62: ='SAM Build'!E126 | E62: ='SAM Build'!C126
A65: x | B65: §7 - Target scenario matrix (1 = targets bucket)
...

Sheet TAM Build
B2: TAM Build
B4: §1 - Headline TAM
B6: Measure | C6: Value
B7: Cumulative portfolio TAM (FY22-27) | C7: ='TAM Build'!C141
B8: Average annual portfolio TAM | C8: ='TAM Build'!C143
B9: incl. OBBBA mandatory TAM (Sec. 20002(16)) | C9: ='TAM Build'!C146
B10: Virginia BC coefficient (Block V announced POP) | C10: ='TAM Build'!C62
B11: Columbia BC coefficient (Build I announced POP) | C11: ='TAM Build'!C63
B12: AP/LLTM reference coefficient | C12: ='TAM Build'!C65
A15: x | B15: §2 - Budget normalized (TAM stream bases per class/FY)
A17: x | B17: §2a - Applied stream toggles (1 = include)
B19: Toggle | C19: Value
B20: Include BC stream | C20: ='Assumptions'!C17
B21: Include AP/LLTM stream | C21: ='Assumptions'!C18
B22: Include OBBBA mandatory (Sec. 20002(16)) | C22: ='Assumptions'!C19
A24: x | B24: §2b - Virginia (LI 2013) stream bases ($M, FY22-27)
B26: Metric | C26: 2022 | D26: 2023 | E26: 2024 | F26: 2025 | G26: 2026 | H26: 2027
B27: BC base (P-5c Basic Construction) | C27: ='SCN Budget'!C54 | D27: ='SCN Budget'!D54 | E27: ='SCN Budget'!E54 | F27: ='SCN Budget'!F54 | G27: ='SCN Budget'!G54 | H27: ='SCN Budget'!H54
B28: AP/LLTM base (P-10, confirmed 0) | C28: ='Assumptions'!C33 | D28: ='Assumptions'!D33 | E28: ='Assumptions'!E33 | F28: ='Assumptions'!F33 | G28: ='Assumptions'!G33 | H28: ='Assumptions'!H33
B29: Less: prior-yr AP credit | C29: 0 | D29: 0 | E29: 0 | F29: 0 | G29: 0 | H29: 0
B30: OBBBA mandatory BC base (Sec. 20002(16)) | C30: ='OBBBA Mandatory'!C43 | D30: ='OBBBA Mandatory'!D43 | E30: ='OBBBA Mandatory'!E43 | F30: ='OBBBA Mandatory'!F43 | G30: ='OBBBA Mandatory'!G43 | H30: ='OBBBA Mandatory'!H43
B31: BC base in TAM | C31: =IF(C27=0,"",'Assumptions'!C17*C27) | D31: =IF(D27=0,"",'Assumptions'!C17*D27) | E31: =IF(E27=0,"",'Assumptions'!C17*E27) | F31: =IF(F27=0,"",'Assumptions'!C17*F27) | G31: =IF(G27=0,"",'Assumptions'!C17*G27) | H31: =IF(H27=0,"",'Assumptions'!C17*H27)
B32: AP/LLTM base in TAM | C32: =IF(C28=0,"",'Assumptions'!C18*(C28-C29)) | D32: =IF(D28=0,"",'Assumptions'!C18*(D28-D29)) | E32: =IF(E28=0,"",'Assumptions'!C18*(E28-E29)) | F32: =IF(F28=0,"",'Assumptions'!C18*(F28-F29)) | G32: =IF(G28=0,"",'Assumptions'!C18*(G28-G29)) | H32: =IF(H28=0,"",'Assumptions'!C18*(H28-H29))
B33: OBBBA base in TAM | C33: =IF(N(C30)=0,"",'Assumptions'!C19*C30) | D33: =IF(N(D30)=0,"",'Assumptions'!C19*D30) | E33: =IF(N(E30)=0,"",'Assumptions'!C19*E30) | F33: =IF(N(F30)=0,"",'Assumptions'!C19*F30) | G33: =IF(N(G30)=0,"",'Assumptions'!C19*G30) | H33: =IF(N(H30)=0,"",'Assumptions'!C19*H30)
B34: TAM base (BC + AP/LLTM + OBBBA) | C34: =N(C31)+N(C32)+N(C33) | D34: =N(D31)+N(D32)+N(D33) | E34: =N(E31)+N(E32)+N(E33) | F34: =N(F31)+N(F32)+N(F33) | G34: =N(G31)+N(G32)+N(G33) | H34: =N(H31)+N(H32)+N(H33)
A36: x | B36: §2c - Columbia (LI 1045) stream bases ($M, FY22-27)
B38: Metric | C38: 2022 | D38: 2023 | E38: 2024 | F38: 2025 | G38: 2026 | H38: 2027
B39: BC base (P-5c Basic Construction) | C39: ='SCN Budget'!C96 | D39: ='SCN Budget'!D96 | E39: ='SCN Budget'!E96 | F39: ='SCN Budget'!F96 | G39: ='SCN Budget'!G96 | H39: ='SCN Budget'!H96
B40: AP/LLTM base (P-10, confirmed 0) | C40: ='Assumptions'!C34 | D40: ='Assumptions'!D34 | E40: ='Assumptions'!E34 | F40: ='Assumptions'!F34 | G40: ='Assumptions'!G34 | H40: ='Assumptions'!H34
B41: Less: prior-yr AP credit | C41: 0 | D41: 0 | E41: 0 | F41: 0 | G41: 0 | H41: 0
B42: OBBBA mandatory BC base (Sec. 20002(16)) | C42: ='OBBBA Mandatory'!C44 | D42: ='OBBBA Mandatory'!D44 | E42: ='OBBBA Mandatory'!E44 | F42: ='OBBBA Mandatory'!F44 | G42: ='OBBBA Mandatory'!G44 | H42: ='OBBBA Mandatory'!H44
B43: BC base in TAM | C43: =IF(C39=0,"",'Assumptions'!C17*C39) | D43: =IF(D39=0,"",'Assumptions'!C17*D39) | E43: =IF(E39=0,"",'Assumptions'!C17*E39) | F43: =IF(F39=0,"",'Assumptions'!C17*F39) | G43: =IF(G39=0,"",'Assumptions'!C17*G39) | H43: =IF(H39=0,"",'Assumptions'!C17*H39)
B44: AP/LLTM base in TAM | C44: =IF(C40=0,"",'Assumptions'!C18*(C40-C41)) | D44: =IF(D40=0,"",'Assumptions'!C18*(D40-D41)) | E44: =IF(E40=0,"",'Assumptions'!C18*(E40-E41)) | F44: =IF(F40=0,"",'Assumptions'!C18*(F40-F41)) | G44: =IF(G40=0,"",'Assumptions'!C18*(G40-G41)) | H44: =IF(H40=0,"",'Assumptions'!C18*(H40-H41))
B45: OBBBA base in TAM | C45: =IF(N(C42)=0,"",'Assumptions'!C19*C42) | D45: =IF(N(D42)=0,"",'Assumptions'!C19*D42) | E45: =IF(N(E42)=0,"",'Assumptions'!C19*E42) | F45: =IF(N(F42)=0,"",'Assumptions'!C19*F42) | G45: =IF(N(G42)=0,"",'Assumptions'!C19*G42) | H45: =IF(N(H42)=0,"",'Assumptions'!C19*H42)
B46: TAM base (BC + AP/LLTM + OBBBA) | C46: =N(C43)+N(C44)+N(C45) | D46: =N(D43)+N(D44)+N(D45) | E46: =N(E43)+N(E44)+N(E45) | F46: =N(F43)+N(F44)+N(F45) | G46: =N(G43)+N(G44)+N(G45) | H46: =N(H43)+N(H44)+N(H45)
A48: x | B48: §2d - Portfolio stream-base totals (Va + Col)
B50: Metric | C50: 2022 | D50: 2023 | E50: 2024 | F50: 2025 | G50: 2026 | H50: 2027
B51: BC base in TAM | C51: =N(C31)+N(C43) | D51: =N(D31)+N(D43) | E51: =N(E31)+N(E43) | F51: =N(F31)+N(F43) | G51: =N(G31)+N(G43) | H51: =N(H31)+N(H43)
B52: AP/LLTM base in TAM | C52: =N(C32)+N(C44) | D52: =N(D32)+N(D44) | E52: =N(E32)+N(E44) | F52: =N(F32)+N(F44) | G52: =N(G32)+N(G44) | H52: =N(H32)+N(H44)
B53: OBBBA base in TAM | C53: =N(C33)+N(C45) | D53: =N(D33)+N(D45) | E53: =N(E33)+N(E45) | F53: =N(F33)+N(F45) | G53: =N(G33)+N(G45) | H53: =N(H33)+N(H45)
...

Sheet SAM Build
B2: SAM Build
B4: §1 - SAM scenario menu
B6: Measure | C6: Value
B7: Broad component-mfg SAM (avg annual FY22-27) | C7: ='SAM Build'!C120
B8: Broad component-mfg SAM (FY22-27 cumulative) | C8: ='SAM Build'!D120
B9: Broad SAM as % of TAM | C9: ='SAM Build'!E120
B10: Selected SAM scenario | C10: ='Assumptions'!C11
B11: Selected SAM (avg annual) | C11: ='SAM Build'!C126
A14: x | B14: §2 - Scenario matrix
B16: Bucket | C16: Metal | D16: HM&E | E16: Electrical | F16: Modular | G16: Broad
B17: Structural fabrication & modules | C17: ='Assumptions'!C69 | D17: ='Assumptions'!D69 | E17: ='Assumptions'!E69 | F17: ='Assumptions'!F69 | G17: ='Assumptions'!G69
B18: Machining / mechanical / propulsion | C18: ='Assumptions'!C70 | D18: ='Assumptions'!D70 | E18: ='Assumptions'!E70 | F18: ='Assumptions'!F70 | G18: ='Assumptions'!G70
B19: Castings & forgings | C19: ='Assumptions'!C71 | D19: ='Assumptions'!D71 | E19: ='Assumptions'!E71 | F19: ='Assumptions'!F71 | G19: ='Assumptions'!G71
B20: Piping / fluid handling | C20: ='Assumptions'!C72 | D20: ='Assumptions'!D72 | E20: ='Assumptions'!E72 | F20: ='Assumptions'!F72 | G20: ='Assumptions'!G72
B21: Electrical power / distribution / generation | C21: ='Assumptions'!C73 | D21: ='Assumptions'!D73 | E21: ='Assumptions'!E73 | F21: ='Assumptions'!F73 | G21: ='Assumptions'!G73
B22: HVAC / ventilation / chilled water | C22: ='Assumptions'!C74 | D22: ='Assumptions'!D74 | E22: ='Assumptions'!E74 | F22: ='Assumptions'!F74 | G22: ='Assumptions'!G74
B23: Coatings / insulation / decking | C23: ='Assumptions'!C75 | D23: ='Assumptions'!D75 | E23: ='Assumptions'!E75 | F23: ='Assumptions'!F75 | G23: ='Assumptions'!G75
A26: x | B26: §3 - Modeled bucket shares by FY (gated evidence + Inputs adjustment)
A28: x | B28: §3a - Virginia (= Worktype by FY observed + adjustment; FY26-27 use the window vector)
B30: Bucket | C30: Adj (Inputs) | D30: FY2022 | E30: FY2023 | F30: FY2024 | G30: FY2025 | H30: FY26-27 (window)
B31: Structural fabrication & modules | C31: ='Assumptions'!C81 | D31: =N('Worktype by FY'!C31)+$C31 | E31: =N('Worktype by FY'!D31)+$C31 | F31: =N('Worktype by FY'!E31)+$C31 | G31: =N('Worktype by FY'!F31)+$C31 | H31: =N('Worktype by FY'!G31)+$C31
B32: Machining / mechanical / propulsion | C32: ='Assumptions'!C82 | D32: =N('Worktype by FY'!C32)+$C32 | E32: =N('Worktype by FY'!D32)+$C32 | F32: =N('Worktype by FY'!E32)+$C32 | G32: =N('Worktype by FY'!F32)+$C32 | H32: =N('Worktype by FY'!G32)+$C32
B33: Castings & forgings | C33: ='Assumptions'!C83 | D33: =N('Worktype by FY'!C33)+$C33 | E33: =N('Worktype by FY'!D33)+$C33 | F33: =N('Worktype by FY'!E33)+$C33 | G33: =N('Worktype by FY'!F33)+$C33 | H33: =N('Worktype by FY'!G33)+$C33
B34: Piping / fluid handling | C34: ='Assumptions'!C84 | D34: =N('Worktype by FY'!C34)+$C34 | E34: =N('Worktype by FY'!D34)+$C34 | F34: =N('Worktype by FY'!E34)+$C34 | G34: =N('Worktype by FY'!F34)+$C34 | H34: =N('Worktype by FY'!G34)+$C34
B35: Electrical power / distribution / generation | C35: ='Assumptions'!C85 | D35: =N('Worktype by FY'!C35)+$C35 | E35: =N('Worktype by FY'!D35)+$C35 | F35: =N('Worktype by FY'!E35)+$C35 | G35: =N('Worktype by FY'!F35)+$C35 | H35: =N('Worktype by FY'!G35)+$C35
B36: HVAC / ventilation / chilled water | C36: ='Assumptions'!C86 | D36: =N('Worktype by FY'!C36)+$C36 | E36: =N('Worktype by FY'!D36)+$C36 | F36: =N('Worktype by FY'!E36)+$C36 | G36: =N('Worktype by FY'!F36)+$C36 | H36: =N('Worktype by FY'!G36)+$C36
B37: Coatings / insulation / decking | C37: ='Assumptions'!C87 | D37: =N('Worktype by FY'!C37)+$C37 | E37: =N('Worktype by FY'!D37)+$C37 | F37: =N('Worktype by FY'!E37)+$C37 | G37: =N('Worktype by FY'!F37)+$C37 | H37: =N('Worktype by FY'!G37)+$C37
B38: Unbucketed / ambiguous | D38: =1-SUM(D31:D37) | E38: =1-SUM(E31:E37) | F38: =1-SUM(F31:F37) | G38: =1-SUM(G31:G37) | H38: =1-SUM(H31:H37)
B39: Total modeled share | D39: =SUM(D31:D38) | E39: =SUM(E31:E38) | F39: =SUM(F31:F38) | G39: =SUM(G31:G38) | H39: =SUM(H31:H38)
A42: x | B42: §3b - Columbia (= Worktype by FY observed + adjustment; FY26-27 use the window vector)
B44: Bucket | C44: Adj (Inputs) | D44: FY2022 | E44: FY2023 | F44: FY2024 | G44: FY2025 | H44: FY26-27 (window)
B45: Structural fabrication & modules | C45: ='Assumptions'!C81 | D45: =N('Worktype by FY'!C59)+$C45 | E45: =N('Worktype by FY'!D59)+$C45 | F45: =N('Worktype by FY'!E59)+$C45 | G45: =N('Worktype by FY'!F59)+$C45 | H45: =N('Worktype by FY'!G59)+$C45
B46: Machining / mechanical / propulsion | C46: ='Assumptions'!C82 | D46: =N('Worktype by FY'!C60)+$C46 | E46: =N('Worktype by FY'!D60)+$C46 | F46: =N('Worktype by FY'!E60)+$C46 | G46: =N('Worktype by FY'!F60)+$C46 | H46: =N('Worktype by FY'!G60)+$C46
B47: Castings & forgings | C47: ='Assumptions'!C83 | D47: =N('Worktype by FY'!C61)+$C47 | E47: =N('Worktype by FY'!D61)+$C47 | F47: =N('Worktype by FY'!E61)+$C47 | G47: =N('Worktype by FY'!F61)+$C47 | H47: =N('Worktype by FY'!G61)+$C47
B48: Piping / fluid handling | C48: ='Assumptions'!C84 | D48: =N('Worktype by FY'!C62)+$C48 | E48: =N('Worktype by FY'!D62)+$C48 | F48: =N('Worktype by FY'!E62)+$C48 | G48: =N('Worktype by FY'!F62)+$C48 | H48: =N('Worktype by FY'!G62)+$C48
B49: Electrical power / distribution / generation | C49: ='Assumptions'!C85 | D49: =N('Worktype by FY'!C63)+$C49 | E49: =N('Worktype by FY'!D63)+$C49 | F49: =N('Worktype by FY'!E63)+$C49 | G49: =N('Worktype by FY'!F63)+$C49 | H49: =N('Worktype by FY'!G63)+$C49
B50: HVAC / ventilation / chilled water | C50: ='Assumptions'!C86 | D50: =N('Worktype by FY'!C64)+$C50 | E50: =N('Worktype by FY'!D64)+$C50 | F50: =N('Worktype by FY'!E64)+$C50 | G50: =N('Worktype by FY'!F64)+$C50 | H50: =N('Worktype by FY'!G64)+$C50
B51: Coatings / insulation / decking | C51: ='Assumptions'!C87 | D51: =N('Worktype by FY'!C65)+$C51 | E51: =N('Worktype by FY'!D65)+$C51 | F51: =N('Worktype by FY'!E65)+$C51 | G51: =N('Worktype by FY'!F65)+$C51 | H51: =N('Worktype by FY'!G65)+$C51
B52: Unbucketed / ambiguous | D52: =1-SUM(D45:D51) | E52: =1-SUM(E45:E51) | F52: =1-SUM(F45:F51) | G52: =1-SUM(G45:G51) | H52: =1-SUM(H45:H51)
B53: Total modeled share | D53: =SUM(D45:D52) | E53: =SUM(E45:E52) | F53: =SUM(F45:F52) | G53: =SUM(G45:G52) | H53: =SUM(H45:H52)
...

Sheet Outlook
B2: Outlook
B4: §1 - Penetration & outyear outlook
B6: Measure | C6: Value
B7: Virginia outsourced penetration, FY22-25 (outyear low) | C7: =C33
B8: Columbia outsourced penetration, FY22-25 (outyear low) | C8: =C34
B9: Implied outyear Outsourced BC, low $M/yr | C9: =C60
B10: Implied outyear Outsourced BC, high $M/yr | C10: =C61
B11: FY22-25 average annual TAM $M/yr | C11: =C69
A14: x | B14: §2 - Outsourced BC penetration by FY (constant FY2026 $, per class)
B16: Metric | C16: 2022 | D16: 2023 | E16: 2024 | F16: 2025 | G16: 2026 | H16: 2027
B17: Virginia Outsourced BC TAM incl. OBBBA stream ($M) | C17: =N('TAM Build'!C116) | D17: =N('TAM Build'!D116) | E17: =N('TAM Build'!E116) | F17: =N('TAM Build'!F116) | G17: =N('TAM Build'!G116) | H17: =N('TAM Build'!H116)
B18: Columbia Outsourced BC TAM ($M) | C18: =N('TAM Build'!C127) | D18: =N('TAM Build'!D127) | E18: =N('TAM Build'!E127) | F18: =N('TAM Build'!F127) | G18: =N('TAM Build'!G127) | H18: =N('TAM Build'!H127)
B19: Outsourced BC TAM, all streams (portfolio $M) | C19: =N('TAM Build'!C135) | D19: =N('TAM Build'!D135) | E19: =N('TAM Build'!E135) | F19: =N('TAM Build'!F135) | G19: =N('TAM Build'!G135) | H19: =N('TAM Build'!H135)
B20: Virginia P-5c Total Ship Estimate ($M) | C20: ='SCN Budget'!C44 | D20: ='SCN Budget'!D44 | E20: ='SCN Budget'!E44 | F20: ='SCN Budget'!F44 | G20: ='SCN Budget'!G44 | H20: ='SCN Budget'!H44
B21: plus OBBBA gross award ($M; rides Virginia, toggle-gated, FY27 via spillover) | C21: 0 | D21: 0 | E21: 0 | F21: 0 | G21: =(N('OBBBA Mandatory'!G26)+N('OBBBA Mandatory'!G27))*(1-'Assumptions'!C46)*'Deflators'!D11*'Assumptions'!C19 | H21: =(N('OBBBA Mandatory'!G26)+N('OBBBA Mandatory'!G27))*'Assumptions'!C46*'Deflators'!D12*'Assumptions'!C19
B22: Virginia total spend incl. OBBBA ($M) | C22: =C20+N(C21) | D22: =D20+N(D21) | E22: =E20+N(E21) | F22: =F20+N(F21) | G22: =G20+N(G21) | H22: =H20+N(H21)
B23: Columbia total spend: P-5c Total Ship Estimate ($M) | C23: ='SCN Budget'!C86 | D23: ='SCN Budget'!D86 | E23: ='SCN Budget'!E86 | F23: ='SCN Budget'!F86 | G23: ='SCN Budget'!G86 | H23: ='SCN Budget'!H86
B24: Total ship spend incl. OBBBA (portfolio $M) | C24: =C22+C23 | D24: =D22+D23 | E24: =E22+E23 | F24: =F22+F23 | G24: =G22+G23 | H24: =H22+H23
B25: Virginia penetration: TAM / total spend | C25: =IF(C22=0,"",C17/C22) | D25: =IF(D22=0,"",D17/D22) | E25: =IF(E22=0,"",E17/E22) | F25: =IF(F22=0,"",F17/F22) | G25: =IF(G22=0,"",G17/G22) | H25: =IF(H22=0,"",H17/H22)
B26: Columbia penetration: TAM / total spend | C26: =IF(C23=0,"",C18/C23) | D26: =IF(D23=0,"",D18/D23) | E26: =IF(E23=0,"",E18/E23) | F26: =IF(F23=0,"",F18/F23) | G26: =IF(G23=0,"",G18/G23) | H26: =IF(H23=0,"",H18/H23)
B27: Portfolio penetration: TAM / total ship spend | C27: =IF(C24=0,"",C19/C24) | D27: =IF(D24=0,"",D19/D24) | E27: =IF(E24=0,"",E19/E24) | F27: =IF(F24=0,"",F19/F24) | G27: =IF(G24=0,"",G19/G24) | H27: =IF(H24=0,"",H19/H24)
A30: x | B30: §3 - Window-average penetration (ratio of sums) + outyear assumptions
B32: Measure | C32: Value
B33: Virginia FY22-25 average (sum TAM / sum spend; complete historical years) | C33: =SUM(C17:F17)/SUM(C22:F22)
B34: Columbia FY22-25 average (sum TAM / sum spend; complete historical years) | C34: =SUM(C18:F18)/SUM(C23:F23)
B35: Portfolio FY22-25 average (sum TAM / sum spend; memo) | C35: =SUM(C19:F19)/SUM(C24:F24)
B36: Portfolio FY22-27 average (sum TAM / sum spend; memo) | C36: =SUM(C19:H19)/SUM(C24:H24)
B37: Portfolio FY26-27 average (sum TAM / sum spend; memo) | C37: =SUM(G19:H19)/SUM(G24:H24)
B38: Outsourcing intent uplift (Assumptions §9) | C38: ='Assumptions'!C93
B39: Virginia assumption, low (= class FY22-25 average) | C39: =C33
B40: Virginia assumption, high (= low x (1 + intent uplift)) | C40: =C39*(1+C38)
B41: Columbia assumption, low (= class FY22-25 average) | C41: =C34
B42: Columbia assumption, high (= low x (1 + intent uplift)) | C42: =C41*(1+C38)
B43: Window average = sum of TAM / sum of spend over the window, not the mean of annual ratios.
A46: x | B46: §4 - Implied outyear Outsourced BC (FY2028-FY2031, per class)
B48: Metric | C48: 2028 | D48: 2029 | E48: 2030 | F48: 2031
B49: Virginia FYDP gross, constant FY2026 $M | C49: ='FYDP Outyears'!F33 | D49: ='FYDP Outyears'!G33 | E49: ='FYDP Outyears'!H33 | F49: ='FYDP Outyears'!I33
B50: Columbia FYDP gross, constant FY2026 $M | C50: ='FYDP Outyears'!F34 | D50: ='FYDP Outyears'!G34 | E50: ='FYDP Outyears'!H34 | F50: ='FYDP Outyears'!I34
B51: Portfolio FYDP gross (PB2027 request), constant FY2026 $M | C51: ='FYDP Outyears'!F35 | D51: ='FYDP Outyears'!G35 | E51: ='FYDP Outyears'!H35 | F51: ='FYDP Outyears'!I35
B52: Virginia implied Outsourced BC, low ($M) | C52: =C49*$C$39 | D52: =D49*$C$39 | E52: =E49*$C$39 | F52: =F49*$C$39
...

Sheet Deflators
B2: Deflators
A4: x | B4: §1 - DoD price deflators (Green Book Procurement TOA, rebased FY2026)
B6: FY | C6: Procurement deflator (FY2025=100) | D6: Factor to constant FY2026 $ | E6: Basis
B7: FY2022 | C7: 93.13 | D7: 1.10 | E7: Green Book Table 5-4
B8: FY2023 | C8: 95.77 | D8: 1.07 | E8: Green Book Table 5-4
B9: FY2024 | C9: 97.92 | D9: 1.04 | E9: Green Book Table 5-4
B10: FY2025 | C10: 100 | D10: 1.02 | E10: Green Book Table 5-4
B11: FY2026 | C11: 102.1 | D11: 1.00 | E11: Green Book Table 5-4
B12: FY2027 | C12: 104.24 | D12: 0.98 | E12: Green Book Table 5-4
B13: FY2028 | C13: 106.43 | D13: 0.96 | E13: Green Book Table 5-4
B14: FY2029 | C14: 108.67 | D14: 0.94 | E14: Green Book Table 5-4
B15: FY2030 | C15: 110.95 | D15: 0.92 | E15: Extrapolated @ 2.1%/yr
B16: FY2031 | C16: 113.28 | D16: 0.90 | E16: Extrapolated @ 2.1%/yr
A19: x | B19: §2 - Sources
B21: Series | C21: Source
B22: Green Book Procurement TOA | C22: OSD National Defense Budget Estimates for FY2025 (Green Book), Table 5-4 Procurement TOA, FY2025=100 (pp. 58-59 / PDF pp. 65-66); rebased to FY2026=1.000
B23: FY2030-FY2031 outyears | C23: FY2030-FY2031 extrapolated at 2.1%/yr (Green Book Table 5-3 steady-state purchases inflation); Table 5-4 ends at FY2029

Sheet SCN Budget
B2: SCN Budget
B4: §1 - Basic Construction & GFE by FY ($M)
B6: Measure | C6: 2022 | D6: 2023 | E6: 2024 | F6: 2025 | G6: 2026 | H6: 2027 | I6: Total
B7: Virginia Basic Construction | C7: ='SCN Budget'!C54 | D7: ='SCN Budget'!D54 | E7: ='SCN Budget'!E54 | F7: ='SCN Budget'!F54 | G7: ='SCN Budget'!G54 | H7: ='SCN Budget'!H54 | I7: =SUM(C7:H7)
B8: Columbia Basic Construction | C8: ='SCN Budget'!C96 | D8: ='SCN Budget'!D96 | E8: ='SCN Budget'!E96 | F8: ='SCN Budget'!F96 | G8: ='SCN Budget'!G96 | H8: ='SCN Budget'!H96 | I8: =SUM(C8:H8)
B9: Portfolio Basic Construction | C9: =N('SCN Budget'!C54)+N('SCN Budget'!C96) | D9: =N('SCN Budget'!D54)+N('SCN Budget'!D96) | E9: =N('SCN Budget'!E54)+N('SCN Budget'!E96) | F9: =N('SCN Budget'!F54)+N('SCN Budget'!F96) | G9: =N('SCN Budget'!G54)+N('SCN Budget'!G96) | H9: =N('SCN Budget'!H54)+N('SCN Budget'!H96) | I9: =SUM(C9:H9)
B10: Virginia GFE sum | C10: ='SCN Budget'!C52 | D10: ='SCN Budget'!D52 | E10: ='SCN Budget'!E52 | F10: ='SCN Budget'!F52 | G10: ='SCN Budget'!G52 | H10: ='SCN Budget'!H52 | I10: =SUM(C10:H10)
B11: Columbia GFE sum | C11: ='SCN Budget'!C94 | D11: ='SCN Budget'!D94 | E11: ='SCN Budget'!E94 | F11: ='SCN Budget'!F94 | G11: ='SCN Budget'!G94 | H11: ='SCN Budget'!H94 | I11: =SUM(C11:H11)
B12: Portfolio GFE sum | C12: =N('SCN Budget'!C52)+N('SCN Budget'!C94) | D12: =N('SCN Budget'!D52)+N('SCN Budget'!D94) | E12: =N('SCN Budget'!E52)+N('SCN Budget'!E94) | F12: =N('SCN Budget'!F52)+N('SCN Budget'!F94) | G12: =N('SCN Budget'!G52)+N('SCN Budget'!G94) | H12: =N('SCN Budget'!H52)+N('SCN Budget'!H94) | I12: =SUM(C12:H12)
A15: x | B15: §2 - Virginia (LI 2013) SCN P-5c per FY ($M)
B17: Metric | C17: 2022 | D17: 2023 | E17: 2024 | F17: 2025 | G17: 2026 | H17: 2027
B18: Total Ship Estimate | C18: 6915.757 | D18: 7250.579 | E18: 11377.643 | F18: 9500.534 | G18: 5389.109 | H18: 11437.036
B19: Plans Costs | C19: 252.399 | D19: 192.169 | E19: 207.166 | F19: 2595.816 | G19: 219.603 | H19: 223.443
A21: x | B21: §2a - GFE components
B23: Propulsion Equipment | C23: 1046.83 | D23: 1083.115 | E23: 1121.47 | F23: 1004.95 | G23: 1035.07 | H23: 1273.09
B24: Electronics | C24: 540.536 | D24: 551.346 | E24: 562.372 | F24: 313.264 | G24: 598.515 | H24: 624.898
B25: Hull, Mechanical, Electrical (HM&E) | C25: 139.293 | D25: 141.566 | E25: 144.189 | F25: 98.937 | G25: 150.015 | H25: 153.016
B26: Ordnance
B27: Other Cost | C27: 67.806 | D27: 69.162 | E27: 70.546 | F27: 35.978 | G27: 73.395 | H27: 74.863
B28: Technology Insertion | C28: 15.398 | D28: 15.706 | E28: 16.02 | F28: 16.34 | G28: 16.667 | H28: 17.001
B29: GFE Sum | C29: 1587.366 | D29: 1634.461 | E29: 1683.842 | F29: 1318.214 | G29: 1633.585 | H29: 1897.988
A31: x | B31: §2b - Construction
B33: Change Orders | C33: 95.212 | D33: 102.067 | E33: 185.118 | F33: 108.705 | G33: 159.052 | H33: 181.415
B34: Basic Construction | C34: 4758.283 | D34: 5095.448 | E34: 9070.762 | F34: 5326.544 | G34: 3136.792 | H34: 8889.31
A36: x | B36: §2c - Derived ratios
B38: BC % of Total | C38: =IF(C18=0,"",C34/C18) | D38: =IF(D18=0,"",D34/D18) | E38: =IF(E18=0,"",E34/E18) | F38: =IF(F18=0,"",F34/F18) | G38: =IF(G18=0,"",G34/G18) | H38: =IF(H18=0,"",H34/H18)
B39: GFE % of Total | C39: =IF(C18=0,"",C29/C18) | D39: =IF(D18=0,"",D29/D18) | E39: =IF(E18=0,"",E29/E18) | F39: =IF(F18=0,"",F29/F18) | G39: =IF(G18=0,"",G29/G18) | H39: =IF(H18=0,"",H29/H18)
A41: x | B41: §2d - Constant FY2026 $M (then-year x deflator)
B43: Metric | C43: 2022 | D43: 2023 | E43: 2024 | F43: 2025 | G43: 2026 | H43: 2027
B44: Total Ship Estimate | C44: =C18*'Deflators'!D7 | D44: =D18*'Deflators'!D8 | E44: =E18*'Deflators'!D9 | F44: =F18*'Deflators'!D10 | G44: =G18*'Deflators'!D11 | H44: =H18*'Deflators'!D12
B45: Plans Costs | C45: =C19*'Deflators'!D7 | D45: =D19*'Deflators'!D8 | E45: =E19*'Deflators'!D9 | F45: =F19*'Deflators'!D10 | G45: =G19*'Deflators'!D11 | H45: =H19*'Deflators'!D12
B46: Propulsion Equipment | C46: =C23*'Deflators'!D7 | D46: =D23*'Deflators'!D8 | E46: =E23*'Deflators'!D9 | F46: =F23*'Deflators'!D10 | G46: =G23*'Deflators'!D11 | H46: =H23*'Deflators'!D12
B47: Electronics | C47: =C24*'Deflators'!D7 | D47: =D24*'Deflators'!D8 | E47: =E24*'Deflators'!D9 | F47: =F24*'Deflators'!D10 | G47: =G24*'Deflators'!D11 | H47: =H24*'Deflators'!D12
B48: Hull, Mechanical, Electrical (HM&E) | C48: =C25*'Deflators'!D7 | D48: =D25*'Deflators'!D8 | E48: =E25*'Deflators'!D9 | F48: =F25*'Deflators'!D10 | G48: =G25*'Deflators'!D11 | H48: =H25*'Deflators'!D12
B49: Ordnance | C49: =C26*'Deflators'!D7 | D49: =D26*'Deflators'!D8 | E49: =E26*'Deflators'!D9 | F49: =F26*'Deflators'!D10 | G49: =G26*'Deflators'!D11 | H49: =H26*'Deflators'!D12
B50: Other Cost | C50: =C27*'Deflators'!D7 | D50: =D27*'Deflators'!D8 | E50: =E27*'Deflators'!D9 | F50: =F27*'Deflators'!D10 | G50: =G27*'Deflators'!D11 | H50: =H27*'Deflators'!D12
B51: Technology Insertion | C51: =C28*'Deflators'!D7 | D51: =D28*'Deflators'!D8 | E51: =E28*'Deflators'!D9 | F51: =F28*'Deflators'!D10 | G51: =G28*'Deflators'!D11 | H51: =H28*'Deflators'!D12
B52: GFE Sum | C52: =C29*'Deflators'!D7 | D52: =D29*'Deflators'!D8 | E52: =E29*'Deflators'!D9 | F52: =F29*'Deflators'!D10 | G52: =G29*'Deflators'!D11 | H52: =H29*'Deflators'!D12
B53: Change Orders | C53: =C33*'Deflators'!D7 | D53: =D33*'Deflators'!D8 | E53: =E33*'Deflators'!D9 | F53: =F33*'Deflators'!D10 | G53: =G33*'Deflators'!D11 | H53: =H33*'Deflators'!D12
B54: Basic Construction | C54: =C34*'Deflators'!D7 | D54: =D34*'Deflators'!D8 | E54: =E34*'Deflators'!D9 | F54: =F34*'Deflators'!D10 | G54: =G34*'Deflators'!D11 | H54: =H34*'Deflators'!D12
...

Sheet OBBBA Mandatory
B2: OBBBA Mandatory
B4: §1 - Mandatory funding ($M)
B6: Measure | C6: Value
B7: Gross award (Sec. 20002(16)) $M | C7: =I28
B8: OBBBA BC base in TAM $M (constant FY2026) | C8: =I43+I44
B9: Full-gross sensitivity $M (reference; not applied) | C9: =I28*'TAM Build'!C62
B10: Capacity / cadence memo $M (excluded) | C10: =D57
A13: x | B13: §2 - Source line (OBBBA Sec. 20002, line 16)
B15: Field | C15: Value
B16: Authority | C16: PL 119-21 Title II (OBBBA), Sec. 20002 Shipbuilding, line 16
B17: Title | C17: Second Virginia-class submarine in fiscal year 2026
B18: Program | C18: Virginia class (LI 2013) - one boat, additive to the FY26 discretionary request
B19: Funding type | C19: Mandatory appropriation (reconciliation)
B20: Scope | C20: Full ship procurement (no cost-category breakout)
B21: Award timing | C21: FY2026, alongside the discretionary FY26 boat
B22: Obligation availability | C22: Through 2029-09-30
B23: Booking basis | C23: Budget-year (all in FY2026)
B25: Class | C25: 2022 | D25: 2023 | E25: 2024 | F25: 2025 | G25: 2026 | H25: 2027 | I25: Total
B26: Virginia (LI 2013) | C26: 0 | D26: 0 | E26: 0 | F26: 0 | G26: 4600 | H26: 0 | I26: =SUM(C26:H26)
B27: Columbia (LI 1045) | C27: 0 | D27: 0 | E27: 0 | F27: 0 | G27: 0 | H27: 0 | I27: =SUM(C27:H27)
B28: Total (Va + Col) | C28: =N(C26)+N(C27) | D28: =N(D26)+N(D27) | E28: =N(E26)+N(E27) | F28: =N(F26)+N(F27) | G28: =N(G26)+N(G27) | H28: =N(H26)+N(H27) | I28: =SUM(C28:H28)
A31: x | B31: §3 - BC/GFE bridge (gross x BC share, Assumptions §4)
A33: x | B33: §3a - OBBBA BC base ($M then-year; FY27 = FY26 x spillover)
B35: Class | C35: 2022 | D35: 2023 | E35: 2024 | F35: 2025 | G35: 2026 | H35: 2027 | I35: Total
B36: Virginia (LI 2013) | C36: =C26*'Assumptions'!E49 | D36: =D26*'Assumptions'!E49 | E36: =E26*'Assumptions'!E49 | F36: =F26*'Assumptions'!E49 | G36: =G26*'Assumptions'!E49*(1-'Assumptions'!C46) | H36: =H26*'Assumptions'!E49+G26*'Assumptions'!E49*'Assumptions'!C46 | I36: =SUM(C36:H36)
B37: Columbia (LI 1045) | C37: =C27*'Assumptions'!E49 | D37: =D27*'Assumptions'!E49 | E37: =E27*'Assumptions'!E49 | F37: =F27*'Assumptions'!E49 | G37: =G27*'Assumptions'!E49*(1-'Assumptions'!C46) | H37: =H27*'Assumptions'!E49+G27*'Assumptions'!E49*'Assumptions'!C46 | I37: =SUM(C37:H37)
B38: GFE / non-BC remainder ($M; excluded from TAM) | C38: =N(C28)-N(C36)-N(C37) | D38: =N(D28)-N(D36)-N(D37) | E38: =N(E28)-N(E36)-N(E37) | F38: =N(F28)-N(F36)-N(F37) | G38: =N(G28)-N(G36)-N(G37) | H38: =N(H28)-N(H36)-N(H37) | I38: =SUM(C38:H38)
A40: x | B40: §3b - Constant FY2026 $M (then-year x deflator)
B42: Class | C42: 2022 | D42: 2023 | E42: 2024 | F42: 2025 | G42: 2026 | H42: 2027 | I42: Total
B43: Virginia (LI 2013) | C43: =C36*'Deflators'!D7 | D43: =D36*'Deflators'!D8 | E43: =E36*'Deflators'!D9 | F43: =F36*'Deflators'!D10 | G43: =G36*'Deflators'!D11 | H43: =H36*'Deflators'!D12 | I43: =SUM(C43:H43)
B44: Columbia (LI 1045) | C44: =C37*'Deflators'!D7 | D44: =D37*'Deflators'!D8 | E44: =E37*'Deflators'!D9 | F44: =F37*'Deflators'!D10 | G44: =G37*'Deflators'!D11 | H44: =H37*'Deflators'!D12 | I44: =SUM(C44:H44)
A47: x | B47: §4 - Capacity / cadence evidence ($M; memo, excluded from TAM)
B49: Sec. 20002 item | C49: Description | D49: $M
B50: 20002(1) | C50: Accelerated Training in Defense Mfg ($36.1M CLB + $213.9M VCS wage) | D50: 250
B51: 20002(2) | C51: Turbine generators, second supplier (1+2 Columbia/Virginia cadence) | D51: 250
B52: 20002(3) | C52: Additive mfg / weld wire / machining capacity (incl. CLB productivity) | D52: 450
B53: 20002(10) | C53: Advanced mfg techniques at EB and NNS (factory of the future) | D53: 500
B54: 20002(13) | C54: MIB workforce development ($48M CLB + $402M VCS) | D54: 450
B55: 20002(14) | C55: Supplier development, sequence-critical suppliers | D55: 750
B56: 20002(15) | C56: Advanced mfg processes across naval shipbuilding IB | D56: 250
...

Sheet AP Bridge
B2: AP Bridge
B4: §1 - P-10 -> TAM bridge ($M, FY22-27)
B6: Step | C6: $M
B7: P-10 gross AP top-line | C7: ='AP Bridge'!C62
B8: less GFE / design / weapons | C8: ='AP Bridge'!C63
B9: less already inside P-5c BC | C9: ='AP Bridge'!C64
B10: less un-itemized overlap | C10: ='AP Bridge'!C65
B11: AP/LLTM additive base | C11: ='AP Bridge'!C66
A14: x | B14: §2 - Virginia (LI 2013) P-10 AP buckets ($M, FY20-31)
B16: Bucket | C16: 2020 | D16: 2021 | E16: 2022 | F16: 2023 | G16: 2024 | H16: 2025 | I16: 2026 | J16: 2027 | K16: 2028 | L16: 2029 | M16: 2030 | N16: 2031 | O16: Total
B17: Plans / SIB | G17: 200 | I17: 130 | J17: 1768.17 | K17: 1943.72 | L17: 1602.69 | M17: 285 | N17: 214 | O17: =SUM(C17:N17)
B18: EOQ | C18: 881.964 | D18: 427.42 | G18: 1360.037 | H18: 1298.349 | I18: 707.862 | L18: 1501.595 | M18: 1433.476 | N18: 781.536 | O18: =SUM(C18:N18)
B19: Nuclear plant LLTM | C19: 1246.83 | D19: 883.115 | E19: 1121.47 | F19: 1004.95 | G19: 1035.07 | H19: 1273.09 | I19: 1336.59 | J19: 1403.49 | K19: 1473.6 | L19: 1547.4 | M19: 1624.8 | N19: 1706.17 | O19: =SUM(C19:N19)
B20: Propulsor LLTM | E20: 47.214 | F20: 48.538 | G20: 49.508 | H20: 50.498 | I20: 51.508 | J20: 52.538 | K20: 53.589 | L20: 54.662 | M20: 55.755 | N20: 56.87 | O20: =SUM(C20:N20)
B21: Electronics LLTM | C21: 29.94 | D21: 30.54 | E21: 31.15 | F21: 31.774 | G21: 32.408 | H21: 33.056 | I21: 33.718 | J21: 34.392 | K21: 35.08 | L21: 35.783 | M21: 36.497 | N21: 37.227 | O21: =SUM(C21:N21)
B22: HM&E LLTM | O22: =SUM(C22:N22)
B23: Ordnance LLTM | O23: =SUM(C23:N23)
B24: Missile compartment LLTM | O24: =SUM(C24:N24)
B25: Shipbuilder-procured LLTM | O25: =SUM(C25:N25)
B26: Shipbuilder-procured LLTM (CFE) | C26: 542.963 | D26: 542.188 | E26: 533.556 | F26: 723.879 | G26: 681.759 | H26: 1065.31 | I26: 867.138 | J26: 885.028 | K26: 979.344 | L26: 959.318 | M26: 878.146 | N26: 895.709 | O26: =SUM(C26:N26)
B27: Class total | C27: =SUM(C17:C26) | D27: =SUM(D17:D26) | E27: =SUM(E17:E26) | F27: =SUM(F17:F26) | G27: =SUM(G17:G26) | H27: =SUM(H17:H26) | I27: =SUM(I17:I26) | J27: =SUM(J17:J26) | ... O27: =SUM(O17:O26)
A30: x | B30: §3 - Columbia (LI 1045) P-10 AP buckets ($M, FY20-31)
B32: Bucket | C32: 2020 | D32: 2021 | E32: 2022 | F32: 2023 | G32: 2024 | H32: 2025 | I32: 2026 | J32: 2027 | K32: 2028 | L32: 2029 | M32: 2030 | N32: 2031 | O32: Total
B33: Plans / SIB | C33: 872.662 | D33: 85 | E33: 110 | F33: 541 | G33: 2355 | H33: 2077.189 | I33: 1692.249 | J33: 809.679 | K33: 1018.316 | L33: 709.136 | M33: 624.179 | N33: 631.272 | O33: =SUM(C33:N33)
B34: EOQ | C34: 77.793 | D34: 79.705 | E34: 176.23 | F34: 141.512 | G34: 778.925 | H34: 494.301 | I34: 382.154 | J34: 178.331 | K34: 191.647 | L34: 18.57 | M34: 1017.969 | N34: 695.466 | O34: =SUM(C34:N34)
B35: Nuclear plant LLTM | D35: 816.737 | E35: 797.262 | F35: 772.686 | G35: 1272.405 | H35: 1526.697 | I35: 1440.528 | J35: 1490.144 | K35: 1544.116 | L35: 1602.529 | M35: 1665.462 | N35: 1777.679 | O35: =SUM(C35:N35)
B36: Propulsor LLTM | O36: =SUM(C36:N36)
B37: Electronics LLTM | C37: 36.39 | E37: 8.097 | F37: 26.587 | G37: 8.43 | H37: 129.354 | I37: 110.601 | J37: 81.76 | K37: 83.395 | L37: 85.063 | M37: 86.765 | N37: 88.499 | O37: =SUM(C37:N37)
B38: HM&E LLTM | C38: 41.948 | D38: 3.1 | E38: 42.857 | F38: 86.285 | G38: 66.824 | H38: 75.475 | I38: 86.202 | J38: 74.393 | K38: 119.156 | L38: 78.284 | M38: 79.138 | N38: 80.929 | O38: =SUM(C38:N38)
B39: Ordnance LLTM | C39: 93.73 | D39: 6.324 | E39: 123.597 | F39: 208.688 | G39: 168.772 | H39: 217.702 | I39: 232.551 | J39: 255.312 | K39: 277.555 | L39: 222.425 | M39: 279.101 | N39: 172.641 | O39: =SUM(C39:N39)
B40: Missile compartment LLTM | C40: 83.747 | D40: 86.288 | E40: 177.391 | F40: 221.311 | G40: 174.136 | H40: 216.261 | I40: 261.29 | J40: 297.347 | K40: 301.02 | L40: 309.689 | M40: 320.267 | N40: 271.046 | O40: =SUM(C40:N40)
B41: Shipbuilder-procured LLTM | C41: 614.657 | D41: 176.021 | E41: 338.546 | F41: 780.484 | G41: 521.242 | H41: 1478.96 | I41: 1145.191 | J41: 1576.376 | K41: 1828.24 | L41: 1890.927 | M41: 2005.869 | N41: 1999.211 | O41: =SUM(C41:N41)
B42: Shipbuilder-procured LLTM (CFE) | O42: =SUM(C42:N42)
B43: Class total | C43: =SUM(C33:C42) | D43: =SUM(D33:D42) | E43: =SUM(E33:E42) | F43: =SUM(F33:F42) | G43: =SUM(G33:G42) | H43: =SUM(H33:H42) | I43: =SUM(I33:I42) | J43: =SUM(J33:J42) | ... O43: =SUM(O33:O42)
A46: x | B46: §4 - P-10 bucket -> TAM treatment (AP/LLTM base = 0)
B48: P-10 bucket | C48: TAM treatment | D48: Rationale
B49: Nuclear plant LLTM | C49: EXCL GFE | D49: BPMI naval reactor - GFE
B50: Electronics LLTM | C50: EXCL GFE | D50: combat-system electronics - Navy-furnished
B51: Ordnance LLTM | C51: EXCL wpn | D51: WPN/OPN ordnance, not SCN
B52: Missile compartment LLTM | C52: EXCL GFE | D52: CMC / tubes - GFE / industrial base
...

Sheet FYDP Outyears
B2: FYDP Outyears
A4: x | B4: §1 - Source exhibit (P-40 Resource Summary, PB2027)
B6: Field | C6: Value
B7: Exhibit | C7: PB 2027 Navy, Exhibit P-40 (1611N Shipbuilding and Conversion, Navy)
B8: Programs | C8: Virginia class (LI 2013) and Columbia class (LI 1045)
B9: Vintage | C9: PB2027 (April 2026); FY2028-FY2031 are the budget request, not appropriation
B10: Columns | C10: FY2027 = FY 2027 Total (Base + OOC); FY2028-FY2031 = FYDP outyears
B11: Refresh | C11: At PB2028: re-tie FY2027 gross to SCN Budget and re-base the outyears
A13: x | B13: §1a - Virginia (LI 2013), then-year $M
B15: Metric | C15: 2025 | D15: 2026 | E15: 2027 | F15: 2028 | G15: 2029 | H15: 2030 | I15: 2031
B16: Gross / Weapon System Cost, then-year $M | C16: 9500.534 | D16: 5389.109 | E16: 11437.036 | F16: 11284.824 | G16: 11098.426 | H16: 10196.613 | I16: 10594.23
B17: Procurement quantity (ships) | C17: 1 | D17: 1 | E17: 2 | F17: 2 | G17: 2 | H17: 2 | I17: 2
B18: Net Procurement (P-1), then-year $M (memo) | C18: 7356.904 | D18: 2740.305 | E18: 8402.316 | F18: 8149.065 | G18: 7876.466 | H18: 7283.37 | I18: 7423.079
B19: Total Obligation Authority, then-year $M (memo) | C19: 13320.211 | D19: 6377.536 | E19: 13151.309 | F19: 13011.118 | G19: 14686.814 | H19: 12268.711 | I19: 12016.801
A21: x | B21: §1b - Columbia (LI 1045), then-year $M
B23: Metric | C23: 2025 | D23: 2026 | E23: 2027 | F23: 2028 | G23: 2029 | H23: 2030 | I23: 2031
B24: Gross / Weapon System Cost, then-year $M | C24: 0 | D24: 10744.317 | E24: 10486.369 | F24: 10137.078 | G24: 10360.998 | H24: 10441.001 | I24: 10693.082
B25: Procurement quantity (ships) | D25: 1 | E25: 1 | F25: 1 | G25: 1 | H25: 1 | I25: 1
B26: Net Procurement (P-1), then-year $M (memo) | C26: 0 | D26: 3928.828 | E26: 6904.785 | F26: 6379.022 | G26: 6057.819 | H26: 6011.645 | I26: 6303.401
B27: Total Obligation Authority, then-year $M (memo) | C27: 9580.774 | D27: 9279.594 | E27: 15583.102 | F27: 12834.863 | G27: 11351.481 | H27: 12359.708 | I27: 12020.144
A30: x | B30: §2 - Constant FY2026 $M (then-year x deflator)
B32: Class | C32: 2025 | D32: 2026 | E32: 2027 | F32: 2028 | G32: 2029 | H32: 2030 | I32: 2031
B33: Virginia (LI 2013) | C33: =C16*'Deflators'!D10 | D33: =D16*'Deflators'!D11 | E33: =E16*'Deflators'!D12 | F33: =F16*'Deflators'!D13 | G33: =G16*'Deflators'!D14 | H33: =H16*'Deflators'!D15 | I33: =I16*'Deflators'!D16
B34: Columbia (LI 1045) | C34: =C24*'Deflators'!D10 | D34: =D24*'Deflators'!D11 | E34: =E24*'Deflators'!D12 | F34: =F24*'Deflators'!D13 | G34: =G24*'Deflators'!D14 | H34: =H24*'Deflators'!D15 | I34: =I24*'Deflators'!D16
B35: Portfolio (Va + Col), constant FY2026 $M | C35: =N(C33)+N(C34) | D35: =N(D33)+N(D34) | E35: =N(E33)+N(E34) | F35: =N(F33)+N(F34) | G35: =N(G33)+N(G34) | H35: =N(H33)+N(H34) | I35: =N(I33)+N(I34)

Sheet POP Corpus
B2: POP Corpus
B4: §1 - Gated POP corpus
B6: Measure | C6: Value
B7: Rows in corpus | C7: 658
B8: Gated TAM actions | C8: =SUMPRODUCT('POP Corpus'!H17:H674)
B9: Gated TAM corpus $M | C9: =SUMPRODUCT('POP Corpus'!H17:H674*'POP Corpus'!K17:K674)
B10: In-scope non-GFE $M | C10: =SUMPRODUCT('POP Corpus'!H17:H674*(1-'POP Corpus'!I17:I674)*'POP Corpus'!K17:K674)
B11: Confirmed in-scope $M | C11: =SUMPRODUCT('POP Corpus'!H17:H674*(1-'POP Corpus'!I17:I674)*'POP Corpus'!J17:J674*'POP Corpus'!K17:K674)
A14: x | B14: §2 - POP corpus (658-row place-of-performance gate)
B16: Date | C16: PIID | D16: Program | E16: Work Type | F16: Scope Class | G16: Stream | H16: Gate | I16: GFE/Excl | J16: Confirmed | K16: $M | L16: EB % | M16: HII % | N16: Other US % | O16: Foreign %
B17: 2026-03-18 | C17: N00024-17-C-2117 | D17: va_or_col | E17: lead_yard | F17: EXCLUDE_REVIEW | G17: BC | H17: 0 | I17: 0 | J17: 1 | K17: 15383.495 | L17: 0.25 | M17: 0.06 | N17: 0.69 | O17: 0
B18: 2025-04-30 | C18: - | D18: va | E18: lltm_early_mfg | F18: INCLUDE_AP_LLTM | G18: AP_LLTM | H18: 1 | I18: 0 | J18: 1 | K18: 12418.145 | L18: 0.4 | M18: 0.32 | N18: 0.28 | O18: 0
B19: 2024-09-24 | C19: N00024-24-C-2473 | D19: non_sub | E19: other | F19: EXCLUDE_REVIEW | G19: BC | H19: 0 | I19: 0 | J19: 1 | K19: 5798.7674 | L19: 0 | M19: 0 | N19: 1 | O19: 0
B20: 2022-12-21 | C20: - | D20: non_sub | E20: advance_procurement | F20: INCLUDE_AP_LLTM | G20: AP_LLTM | H20: 0 | I20: 0 | J20: 1 | K20: 5134.3242 | L20: 0.75 | M20: 0.25 | N20: 0 | O20: 0
B21: 2024-09-24 | C21: N00024-24-C-2467 | D21: non_sub | E21: lltm_early_mfg | F21: INCLUDE_AP_LLTM | G21: AP_LLTM | H21: 0 | I21: 0 | J21: 1 | K21: 3673.3652 | L21: 0 | M21: 0 | N21: 1 | O21: 0
B22: 2022-10-27 | C22: - | D22: non_sub | E22: other | F22: EXCLUDE_REVIEW | G22: BC | H22: 0 | I22: 0 | J22: 1 | K22: 2414 | L22: 0 | M22: 0 | N22: 0.86 | O22: 0
B23: 2026-05-11 | C23: N00024-24-C-2110 | D23: va | E23: lltm_early_mfg | F23: INCLUDE_AP_LLTM | G23: AP_LLTM | H23: 1 | I23: 0 | J23: 1 | K23: 2305.53 | L23: 0 | M23: 0.02 | N23: 0.98 | O23: 0
B24: 2025-06-26 | C24: N00024-24-C-2110 | D24: va | E24: lltm_early_mfg | F24: INCLUDE_AP_LLTM | G24: AP_LLTM | H24: 1 | I24: 0 | J24: 1 | K24: 1851.065 | L24: 0 | M24: 0 | N24: 1 | O24: 0
B25: 2022-09-30 | C25: N00024-18-C-2130 | D25: non_sub | E25: other | F25: EXCLUDE_REVIEW | G25: BC | H25: 0 | I25: 0 | J25: 1 | K25: 1329.68 | L25: 0 | M25: 0 | N25: 1 | O25: 0
B26: 2023-03-31 | C26: - | D26: non_sub | E26: construction | F26: INCLUDE_BC | G26: BC | H26: 0 | I26: 0 | J26: 1 | K26: 1295 | L26: 0 | M26: 0 | N26: 0.89 | O26: 0
B27: 2026-04-02 | C27: N00024-20-C-2120 | D27: va | E27: lead_yard | F27: EXCLUDE_REVIEW | G27: BC | H27: 0 | I27: 0 | J27: 1 | K27: 1265.7904 | L27: 0.92 | M27: 0.08 | N27: 0.01 | O27: 0
B28: 2024-02-23 | C28: - | D28: va | E28: repair_overhaul | F28: EXCLUDE_REVIEW | G28: BC | H28: 0 | I28: 0 | J28: 1 | K28: 1173.178 | L28: 0 | M28: 0 | N28: 0 | O28: 0
... B674: 2024-07-17 | C674: N00024-22-C-2318 | D674: non_sub | E674: other | F674: EXCLUDE_REVIEW | G674: BC | H674: 0 | I674: 0 | J674: 1 | K674: 0 | L674: 0 | M674: 0.04 | N674: 1.96 | O674: 0

Sheet Entity Master
B2: Entity Master
B4: §1 - Supplier-addressable base
B6: Measure | C6: $M / count
B7: Total entities | C7: 928
B8: Supplier-addressable subaward total $M | C8: ='Entity Master'!C972
B9: Prime / co-prime total $M | C9: ='Entity Master'!C955+'Entity Master'!C956
B10: GFE / SIB total $M | C10: ='Entity Master'!C957
B11: Unbucketed supplier $M | C11: ='Entity Master'!C971
A14: x | B14: §2 - Entity classification (registry/NAICS-led; GDEB/Va/Col columns = gated work-type evidence, see Worktype by FY)
B16: Vendor | C16: UEI | D16: Country | E16: NAICS-4 | F16: NAICS desc | G16: $M | H16: Role | I16: Bucket | J16: Class rule | K16: Modular | L16: VLS | M16: GDEB $M | N16: Va FY22 | O16: Va FY23 | P16: Va FY24 | Q16: Va FY25 | R16: Col FY22 | S16: Col FY23 | T16: Col FY24 | U16: Col FY25
B17: NORTHROP GRUMMAN CORPORATION | C17: LCV2N9FVV739 | D17: - | E17: - | F17: - | G17: 1425.3336 | H17: supplier | I17: electrical | J17: registry | K17: 0 | L17: 0 | M17: 1425.3336 | N17: 51.525318 | O17: 414.02604 | P17: 71.544 | Q17: 0 | R17: 4.5125815 | S17: 212.82904 | T17: 125.30586 | U17: 271.22872
B18: LEONARDO SPA | C18: GXPHJRVG9MR7 | D18: ITA | E18: 3364 | F18: Aircraft Manufacturing | G18: 404.38645 | H18: supplier | I18: electrical | J18: registry | K18: 0 | L18: 0 | M18: 404.38645 | N18: -9.4079525 | O18: 0.6217624 | P18: 2.5974007 | Q18: 3.6238726 | R18: 0.17247315 | S18: 245.87679 | T18: 151.60169 | U18: 0
B19: CURTISS-WRIGHT ELECTRO-MECHANICAL CORPORATION | C19: WYDAKCJ5K219 | D19: USA | E19: 3339 | F19: Measuring, Dispensing, and Other Pumping Equipment Manufacturing | G19: 194.47737 | H19: supplier | I19: piping | J19: registry | K19: 0 | L19: 0 | M19: 194.47737 | N19: 9.039718 | O19: 41.387701 | P19: 0 | Q19: 4.2523923 | R19: 30.514753 | S19: 43.525065 | T19: 51.042972 | U19: 14.714772
B20: SCOT FORGE COMPANY | C20: N1PJDANWUJ61 | D20: USA | E20: 3321 | F20: Iron and Steel Forging | G20: 182.25009 | H20: supplier | I20: castings | J20: registry | K20: 0 | L20: 0 | M20: 182.25009 | N20: 3.0361195 | O20: 17.116562 | P20: 8.9640011 | Q20: 23.259703 | R20: 10.304909 | S20: 23.652795 | T20: 43.759235 | U20: 0.8084404
B21: RHOADS METAL FABRICATIONS, INC. | C21: KENVPMBVBT39 | D21: - | E21: - | F21: - | G21: 141.90534 | H21: supplier | I21: structural | J21: registry | K21: 1 | L21: 0 | M21: 141.90534 | N21: 0.0214 | O21: 15.060197 | P21: 1.227004 | Q21: 1.26 | R21: 0.00782888 | S21: 84.327632 | T21: 33.773904 | U21: 6.2273772
B22: DC FABRICATORS INC | C22: E8LNMDLEKM35 | D22: USA | E22: 3323 | F22: Fabricated Structural Metal Manufacturing | G22: 125.67588 | H22: supplier | I22: structural | J22: registry | K22: 1 | L22: 0 | M22: 125.67588 | N22: 6.988434 | O22: 75.327238 | P22: 6.254096 | Q22: 18.791985 | R22: 0.8101452 | S22: 4.412338 | T22: 11.873128 | U22: 1.218518
B23: ESCO TECHNOLOGIES INC. | C23: FLDEFFBLR5P3 | D23: USA | E23: 3252 | F23: Synthetic Rubber Manufacturing | G23: 112.39094 | H23: supplier | I23: coatings | J23: registry | K23: 0 | L23: 0 | M23: 112.39094 | N23: 3.1975621 | O23: 32.764669 | P23: 0.71128515 | Q23: -0.17223018 | R23: 0.03883191 | S23: 0.15003746 | T23: 0.21446425 | U23: 0.04024095
B24: AUSTAL USA, LLC | C24: RG6LJJM6JBS3 | D24: - | E24: - | F24: - | G24: 87.555354 | H24: supplier | I24: structural | J24: registry | K24: 1 | L24: 0 | M24: 87.555354 | N24: 0 | O24: 48.370947 | P24: 14.851728 | Q24: 0 | R24: 5.859715 | S24: 7.3125102 | T24: 11.160454 | U24: 0
B25: ROSYTH ROYAL DOCKYARD LIMITED | C25: LSMBJZFLN8L9 | D25: GBR | E25: 3366 | F25: Ship Building and Repairing | G25: 83.981943 | H25: foreign_fms | I25: - | J25: registry | K25: 0 | L25: 0 | M25: 83.981943 | N25: 0 | O25: 0 | P25: 0 | Q25: 0 | R25: 0 | S25: 22.733711 | T25: 61.248232 | U25: 0
B26: W INTERNATIONAL, LLC | C26: XQW8RJNNAXX8 | D26: USA | E26: 3369 | F26: Military Armored Vehicle, Tank, and Tank Component Manufacturing | G26: 82.602819 | H26: supplier | I26: structural | J26: registry | K26: 1 | L26: 0 | M26: 82.602819 | N26: 6.137467 | O26: 5.5035122 | P26: 7.2701582 | Q26: 8.6312823 | R26: 13.150354 | S26: 29.305468 | T26: 0.9352188 | U26: 10.255118
B27: GRAHAM CORP | C27: F2LEAK3EK9R3 | D27: USA | E27: 3366 | F27: Ship Building and Repairing | G27: 81.594955 | H27: supplier | I27: piping | J27: registry | K27: 0 | L27: 0 | M27: 81.594955 | N27: 0 | O27: 0 | P27: 0 | Q27: 0 | R27: 1.599544 | S27: 30.438141 | T27: 41.909138 | U27: 7.648132
B28: ESCO TECHNOLOGIES INC. | C28: SX6BF52K2WB1 | D28: USA | E28: 5511 | F28: Corporate, Subsidiary, and Regional Managing Offices | G28: 78.062749 | H28: supplier | I28: piping | J28: registry | K28: 0 | L28: 0 | M28: 76.281773 | N28: 0.74 | O28: 0.084264 | P28: 31.677592 | Q28: 9.6978021 | R28: 8.133715 | S28: 2.6352351 | T28: 6.620911 | U28: 0.49422
... B944: TE CONNECTIVITY LTD. | C944: KMDLJAJQ4UM1 | D944: - | E944: - | F944: - | G944: -12.678689 | H944: supplier | I944: electrical | J944: registry | K944: 0 | L944: 0 | M944: -12.678689 | N944: 0.345532 | O944: 0 | P944: 0 | Q944: 0 | R944: 0.033266 | S944: 0 | T944: 0 | U944: 0
A947: x | B947: §3 - Role summary ($ by role; only 'supplier' is addressable)
B949: Role | C949: $M | D949: % of total
B950: supplier | C950: =SUMPRODUCT(('Entity Master'!H17:H944="supplier")*'Entity Master'!G17:G944) | D950: =C950/$C$958
B951: mission_systems | C951: =SUMPRODUCT(('Entity Master'!H17:H944="mission_systems")*'Entity Master'!G17:G944) | D951: =C951/$C$958
B952: service | C952: =SUMPRODUCT(('Entity Master'!H17:H944="service")*'Entity Master'!G17:G944) | D952: =C952/$C$958
B953: holding | C953: =SUMPRODUCT(('Entity Master'!H17:H944="holding")*'Entity Master'!G17:G944) | D953: =C953/$C$958
B954: foreign_fms | C954: =SUMPRODUCT(('Entity Master'!H17:H944="foreign_fms")*'Entity Master'!G17:G944) | D954: =C954/$C$958
B955: prime | C955: =SUMPRODUCT(('Entity Master'!H17:H944="prime")*'Entity Master'!G17:G944) | D955: =C955/$C$958
B956: co_prime | C956: =SUMPRODUCT(('Entity Master'!H17:H944="co_prime")*'Entity Master'!G17:G944) | D956: =C956/$C$958
B957: gfe_sib | C957: =SUMPRODUCT(('Entity Master'!H17:H944="gfe_sib")*'Entity Master'!G17:G944) | D957: =C957/$C$958
B958: Grand total (all recipients) | C958: =SUMPRODUCT('Entity Master'!G17:G944)
A961: x | B961: §4 - Bucket summary (observed supplier $ + share; full corpus reference)
B963: Bucket | C963: Supplier $M | D963: Observed share
B964: Structural fabrication & modules | C964: =SUMPRODUCT(('Entity Master'!H17:H944="supplier")*('Entity Master'!I17:I944="structural")*'Entity Master'!G17:G944) | D964: =C964/$C$972
B965: Machining / mechanical / propulsion | C965: =SUMPRODUCT(('Entity Master'!H17:H944="supplier")*('Entity Master'!I17:I944="machining")*'Entity Master'!G17:G944) | D965: =C965/$C$972
B966: Castings & forgings | C966: =SUMPRODUCT(('Entity Master'!H17:H944="supplier")*('Entity Master'!I17:I944="castings")*'Entity Master'!G17:G944) | D966: =C966/$C$972
B967: Piping / fluid handling | C967: =SUMPRODUCT(('Entity Master'!H17:H944="supplier")*('Entity Master'!I17:I944="piping")*'Entity Master'!G17:G944) | D967: =C967/$C$972
...

Sheet Location Master
B2: Location Master
B4: §1 - Subaward geography (hint only)
B6: Measure | C6: Value
B7: US subaward $M | C7: 5936.7605
B8: Foreign subaward $M | C8: 202.43358
B9: Top state by $M | C9: California
B10: Prime-controlled-state $M | C10: 434.88123
A13: x | B13: §2 - Top 15 states by subaward $ ($M lifetime)
B15: State | C15: Name | D15: $M | E15: % of US | F15: Prime-controlled site
B16: CA | C16: California | D16: 1539.0387 | E16: 0.25923881
B17: PA | C17: Pennsylvania | D17: 759.50389 | E17: 0.12793238
B18: MA | C18: Massachusetts | D18: 578.55799 | E18: 0.097453483
B19: WI | C19: Wisconsin | D19: 473.34805 | E19: 0.079731707
B20: NJ | C20: New Jersey | D20: 301.23721 | E20: 0.050741007
B21: NY | C21: New York | D21: 294.52872 | E21: 0.049611017
B22: IL | C22: Illinois | D22: 219.83682 | E22: 0.03702976
B23: CT | C23: Connecticut | D23: 196.27133 | E23: 0.033060342 | F23: EB (Groton)
B24: VA | C24: Virginia | D24: 184.7383 | E24: 0.031117695 | F24: HII-NNS (Newport News)
B25: FL | C25: Florida | D25: 159.43718 | E25: 0.026855923
B26: OH | C26: Ohio | D26: 138.76447 | E26: 0.02337377
B27: SC | C27: South Carolina | D27: 135.16791 | E27: 0.022767957
B28: TX | C28: Texas | D28: 128.37615 | E28: 0.021623939
B29: NH | C29: New Hampshire | D29: 117.28999 | E29: 0.019756564
B30: MI | C30: Michigan | D30: 107.63751 | E30: 0.018130681
A33: x | B33: §3 - Country distribution (foreign / FMS is excluded scope)
B35: Code | C35: Country | D35: $M | E35: % of total
B36: US | C36: United States | D36: 5936.7605 | E36: 0.96702603
B37: GB | C37: United Kingdom | D37: 160.96134 | E37: 0.026218644
B38: CH | C38: Switzerland | D38: 32.801704 | E38: 0.0053429984
B39: CA | C39: Canada | D39: 8.0001176 | E39: 0.0013031218
B40: DK | C40: Denmark | D40: 0.50955654 | E40: 8.3000559e-05
B41: BR | C41: Brazil | D41: 0.109202 | E41: 1.7787677e-05
B42: CN | C42: China | D42: 0.05165028 | E42: 8.413202e-06
A45: x | B45: §4 - Prime-controlled state flags
B47: State | C47: Site
B48: CT | C48: EB (Groton)
B49: RI | C49: EB (Quonset)
B50: VA | C50: HII-NNS (Newport News)
B51: MS | C51: HII-Ingalls

Sheet Worktype Evidence
B2: Worktype Evidence
B4: §1 - Supplier $ + top vendor per bucket
B6: Bucket | C6: Supplier $M | D6: Top vendor | E6: Evidence count
B7: Structural fabrication & modules | C7: ='Entity Master'!C964 | D7: ='Entity Master'!B21 | E7: 45
B8: Machining / mechanical / propulsion | C8: ='Entity Master'!C965 | D8: ='Entity Master'!B36 | E8: 22
B9: Castings & forgings | C9: ='Entity Master'!C966 | D9: ='Entity Master'!B20 | E9: 10
B10: Piping / fluid handling | C10: ='Entity Master'!C967 | D10: ='Entity Master'!B19 | E10: 62
B11: Electrical power / distribution / generation | C11: ='Entity Master'!C968 | D11: ='Entity Master'!B17 | E11: 33
B12: HVAC / ventilation / chilled water | C12: ='Entity Master'!C969 | D12: ='Entity Master'!B31 | E12: 8
B13: Coatings / insulation / decking | C13: ='Entity Master'!C970 | D13: ='Entity Master'!B23 | E13: 15
B14: Unbucketed / ambiguous | C14: ='Entity Master'!C971 | D14: ='Entity Master'!B81 | E14: 658
A17: x | B17: §2 - Top vendors per bucket (links to Entity Master)
A19: x | B19: §2a - Structural fabrication & modules (top 3 by subaward $)
B21: Rank | C21: Vendor | D21: $M | E21: NAICS desc | F21: Class rule
B22: 1 | C22: ='Entity Master'!B21 | D22: ='Entity Master'!G21 | E22: ='Entity Master'!F21 | F22: ='Entity Master'!J21
B23: 2 | C23: ='Entity Master'!B22 | D23: ='Entity Master'!G22 | E23: ='Entity Master'!F22 | F23: ='Entity Master'!J22
B24: 3 | C24: ='Entity Master'!B24 | D24: ='Entity Master'!G24 | E24: ='Entity Master'!F24 | F24: ='Entity Master'!J24
A26: x | B26: §2b - Machining / mechanical / propulsion (top 3 by subaward $)
B28: Rank | C28: Vendor | D28: $M | E28: NAICS desc | F28: Class rule
B29: 1 | C29: ='Entity Master'!B36 | D29: ='Entity Master'!G36 | E29: ='Entity Master'!F36 | F29: ='Entity Master'!J36
B30: 2 | C30: ='Entity Master'!B58 | D30: ='Entity Master'!G58 | E30: ='Entity Master'!F58 | F30: ='Entity Master'!J58
B31: 3 | C31: ='Entity Master'!B60 | D31: ='Entity Master'!G60 | E31: ='Entity Master'!F60 | F31: ='Entity Master'!J60
A33: x | B33: §2c - Castings & forgings (top 3 by subaward $)
B35: Rank | C35: Vendor | D35: $M | E35: NAICS desc | F35: Class rule
B36: 1 | C36: ='Entity Master'!B20 | D36: ='Entity Master'!G20 | E36: ='Entity Master'!F20 | F36: ='Entity Master'!J20
