Workbook

Sheet Summary
B2: Summary
B3: Every figure is a live formula off the data tabs (no hardcoded constants). Obligations, not ceilings; FY2015-26, pulled 2026-06-23.
B6: §1 - The visibility gap: the same market read three ways
B8: SAM Opportunities portal, USV-relevant notices | C8: =COUNTIF('Portal Notices'!$F$8:$F$676,"usv_autonomy")/COUNTA('Portal Notices'!$F$8:$F$676) | E8: 49 of 669 notices. Source: Portal Notices
B9: SAM Opportunities portal, recurring-sustainment notices | C9: =(COUNTIF('Portal Notices'!$F$8:$F$676,"ship_repair_maintenance")+COUNTIF('Portal Notices'!$F$8:$F$676,"marine_components_parts"))/COUNTA('Portal Notices'!$F$8:$F$676) | E9: ship repair and parts. Source: Portal Notices
B11: Saronic, standard FPDS pull (A-D, IDV), obligated $M | C11: =SUMIFS('OT Layer'!$I$8:$I$843,'OT Layer'!$B$8:$B$843,"SARONIC TECHNOLOGIES",'OT Layer'!$D$8:$D$843,"no") | E11: conventional awards only; OTs are dropped by the feed
B12: Saronic, SAM Contract Awards OT layer, obligated $M | C12: =SUMIFS('OT Layer'!$I$8:$I$843,'OT Layer'!$B$8:$B$843,"SARONIC TECHNOLOGIES",'OT Layer'!$D$8:$D$843,"yes") | E12: the same vendor, the layer FPDS drops
B13: Flagship OT N000242596305 (Navy/PEO-USC), obl / ceiling $M | C13: =SUMIFS('OT Layer'!$I$8:$I$843,'OT Layer'!$C$8:$C$843,"N000242596305") | D13: =SUMIFS('OT Layer'!$H$8:$H$843,'OT Layer'!$C$8:$C$843,"N000242596305") | E13: signed 2025-05-16. Source: OT Layer
B16: §2 - Forward signals: recompete radar and teaming map
B18: Recompete radar, vehicles surfaced (>= $5M) | C18: =COUNTA('Recompete Radar'!$B$8:$B$59) | E18: clock = FPDS ordering-period end; Mechanism 1
B19: ordering period already closed (overdue, no successor seen) | C19: =COUNTIF('Recompete Radar'!$K$8:$K$59,"<0")
B20: reaching turnover within 36 months | C20: =COUNTIFS('Recompete Radar'!$K$8:$K$59,">=0",'Recompete Radar'!$K$8:$K$59,"<=36")
B21: no matching SAM Opportunities notice | C21: =COUNTIF('Recompete Radar'!$N$8:$N$59,"NONE")/COUNTA('Recompete Radar'!$N$8:$N$59) | E21: share with no portal notice
B22: Clocks re-based on FPDS lastDateToOrder (the authoritative ordering-period end); the Stage-2 order-PoP clock ran early or late on 33 of 52. 8 recent IDVs run beyond 36 months.
B24: Teaming map, first-tier subaward edges | C24: =COUNTA('Teaming Edges'!$B$8:$B$688) | E24: reported floor; Mechanism 3
B25: subaward dollars, $M | C25: =SUM('Teaming Edges'!$H$8:$H$688)
B26: distinct subcontractors | C26: =SUMPRODUCT(1/COUNTIF('Teaming Edges'!$E$8:$E$688,'Teaming Edges'!$E$8:$E$688)) | E26: distinct sub keys across the edges
B29: §3 - Market structure: addressable tiers and prime gating
B31: Tier | C31: Awards | D31: Obligated $M | E31: Top-5 prime share
B32: USV / autonomy | C32: =COUNTIF('Market Tiers'!$C$8:$C$5767,"usv_core") | D32: =SUMIF('Market Tiers'!$C$8:$C$5767,"usv_core",'Market Tiers'!$D$8:$D$5767) | E32: =SUMPRODUCT(LARGE(('Prime Concentration'!$B$8:$B$67="usv_core")*'Prime Concentration'!$E$8:$E$67,{1;2;3;4;5}))/100
B33: Small craft | C33: =COUNTIF('Market Tiers'!$C$8:$C$5767,"small_craft") | D33: =SUMIF('Market Tiers'!$C$8:$C$5767,"small_craft",'Market Tiers'!$D$8:$D$5767) | E33: =SUMPRODUCT(LARGE(('Prime Concentration'!$B$8:$B$67="small_craft")*'Prime Concentration'!$E$8:$E$67,{1;2;3;4;5}))/100
B34: Other small vessels | C34: =COUNTIF('Market Tiers'!$C$8:$C$5767,"other_small") | D34: =SUMIF('Market Tiers'!$C$8:$C$5767,"other_small",'Market Tiers'!$D$8:$D$5767) | E34: =SUMPRODUCT(LARGE(('Prime Concentration'!$B$8:$B$67="other_small")*'Prime Concentration'!$E$8:$E$67,{1;2;3;4;5}))/100
B35: Broad maritime | C35: =COUNTIF('Market Tiers'!$C$8:$C$5767,"broad_maritime") | D35: =SUMIF('Market Tiers'!$C$8:$C$5767,"broad_maritime",'Market Tiers'!$D$8:$D$5767) | E35: =SUMPRODUCT(LARGE(('Prime Concentration'!$B$8:$B$67="broad_maritime")*'Prime Concentration'!$E$8:$E$67,{1;2;3;4;5}))/100
B36: Addressable (excl. broad maritime) | C36: =C32+C33+C34 | D36: =D32+D33+D34
B37: Awards and obligated live off Market Tiers (COUNTIF / SUMIF); top-5 share off Prime Concentration.
B39: Addressable awards dark in the portal's 12-month window | C39: =SUMIFS('Award-Opportunity Match'!$G$8:$G$2055,'Award-Opportunity Match'!$I$8:$I$2055,"yes",'Award-Opportunity Match'!$K$8:$K$2055,"NONE")/SUMIFS('Award-Opportunity Match'!$G$8:$G$2055,'Award-Opportunity Match'!$I$8:$I$2055,"yes") | E39: share of in-window addressable $ with no notice. Source: Award-Opportunity Match
B40: 123 of 125 awards; 97 of 99 definitive.
B43: §4 - Backtest: would the radar have flagged recompetes early?
B45: Recompete pairs tested (boat-IDIQ builder chains) | C45: =COUNTA('Backtest Events'!$C$8:$C$18) | E45: point-in-time, no look-ahead
B46: parallel vehicles (predecessor still active, not a recompete) | C46: =COUNTIF('Backtest Events'!$H$8:$H$18,"parallel") | E46: radar correctly stays quiet
B47: true turnovers (predecessor closed around the successor) | C47: =COUNTIF('Backtest Events'!$H$8:$H$18,"<>parallel")
B48: of which anticipable at t-12 months | C48: =COUNTIFS('Backtest Events'!$H$8:$H$18,"<>parallel",'Backtest Events'!$J$8:$J$18,"Y")
B49: predecessor clock extended after t-12 (date-slip) | C49: =COUNTIF('Backtest Events'!$N$8:$N$18,"Y")
B50: The recompete clock (FPDS lastDateToOrder) is set at award, so it is on record 2-6 years before the portal (which showed none of these). A publishable hit-rate needs a solicitationId-linked event set; the builder-chain set conflates recompetes with parallel vehicles.
B53: Sources: USAspending prime awards and subawards; SAM.gov Contract Awards (by awardee UEI); SAM.gov Contract Opportunities. Pulled 2026-06-23, federal FY2015-26.

Sheet OT Layer
B2: OT Layer
B3: One row per award family; obligated and ceiling in $M. OT marks an Other Transaction, which a standard FPDS pull drops.
B5: §1 - USV vendor prime awards, SAM Contract Awards by awardee UEI
B7: Vendor | C7: PIID | D7: OT | E7: Award Type | F7: Base Signed | G7: Last Signed | H7: Ceiling $M | I7: Obligated $M
B8: AUSTAL USA | C8: N0002411C2301 | D8: no | E8: DEFINITIVE CONTRACT | F8: 2012-08-24 | G8: 2025-08-12 | H8: 5642.7 | I8: 4464.7
B9: AUSTAL USA | C9: N0002417C2301 | D9: no | E9: DEFINITIVE CONTRACT | F9: 2020-01-22 | G9: 2025-12-18 | H9: 3098.9 | I9: 2809.9
B10: AUSTAL USA | C10: N0002408C2217 | D10: no | E10: DEFINITIVE CONTRACT | F10: 2018-01-24 | G10: 2023-06-07 | H10: 1673.4 | I10: 1651.8
B11: AUSTAL USA | C11: 70Z02322C93220001 | D11: no | E11: DEFINITIVE CONTRACT | F11: 2026-04-13 | G11: 2026-04-13 | H11: 3311.2 | I11: 1401.2
B12: AUSTAL USA | C12: N0002419C2227 | D12: no | E12: DEFINITIVE CONTRACT | F12: 2022-09-08 | G12: 2026-03-26 | H12: 1882 | I12: 1245.6
B13: TEXTRON SYSTEMS | C13: N0002417C2480 | D13: no | E13: DEFINITIVE CONTRACT | F13: 2017-09-01 | G13: 2025-08-07 | H13: 970.9 | I13: 970.9
B14: TEXTRON SYSTEMS | C14: W911QY17C0013 | D14: no | E14: DEFINITIVE CONTRACT | F14: 2017-01-04 | G14: 2024-08-16 | H14: 705 | I14: 685.9
B15: TEXTRON SYSTEMS | C15: N0002412C2401 | D15: no | E15: DEFINITIVE CONTRACT | F15: 2015-09-16 | G15: 2022-04-08 | H15: 663.2 | I15: 661.6
B16: AUSTAL USA | C16: N0002423C2203 | D16: no | E16: DEFINITIVE CONTRACT | F16: 2024-12-17 | G16: 2025-11-06 | H16: 3196.8 | I16: 631.8
B17: L3HARRIS TECHNOLOGIES | C17: FA881919C0002 | D17: no | E17: DEFINITIVE CONTRACT | F17: 2019-03-21 | G17: 2026-02-24 | H17: 488 | I17: 468.9
B18: AUSTAL USA | C18: N0002421C2209 | D18: no | E18: DEFINITIVE CONTRACT | F18: 2022-03-14 | G18: 2025-07-02 | H18: 520.4 | I18: 416
B19: AUSTAL USA | C19: N0002416C2217 | D19: no | E19: DEFINITIVE CONTRACT | F19: 2018-02-16 | G19: 2019-07-25 | H19: 350.4 | I19: 347.4
... B843: AUSTAL USA | C843: SPRMM120VYA45 | D843: no | E843: PURCHASE ORDER | F843: 2024-06-05 | G843: 2024-06-05 | H843: 0 | I843: 0

Sheet Recompete Radar
B2: Recompete Radar
B3: Clock is the FPDS ordering-period end (lastDateToOrder for an IDV, ultimateCompletionDate for a standalone); an indicator, not a guaranteed date. Clock Basis and Prev Clock show the re-base off the Stage-2 order-PoP. Portal Notice is the matching SAM Opportunities notice.
B5: §1 - Vehicles surfaced by the recompete clock (FPDS ordering-period end)
B7: Vehicle PIID | C7: Tier | D7: Type | E7: Incumbent | F7: NAICS | G7: PSC | H7: Obligated $M | I7: Orders | J7: Recompete Clock | K7: Months to Clock | L7: State | M7: Access Gate | N7: Portal Notice | O7: Last Activity | P7: Clock Basis | Q7: Prev Clock (S2)
B8: N0002409G2300 | C8: other_small | D8: IDV | E8: LOCKHEED MARTIN CORPORATION | F8: 336611 | G8: 1990 | H8: 31.8 | I8: 8 | J8: 2013-10-30 | K8: -151.9 | L8: OVERDUE (ordering period closed, no successor seen) | M8: holders-only (FAR 16.5) | N8: NONE | O8: 2026-03-05 | P8: lastDateToOrder | Q8: 2026-04-30
B9: H9222211D0080 | C9: small_craft | D9: IDV | E9: VIGOR WORKS LLC | F9: 336612 | G9: 1940 | H9: 66.9 | I9: 1 | J9: 2021-11-30 | K9: -54.8 | L9: OVERDUE (ordering period closed, no successor seen) | M9: holders-only (FAR 16.5) | N9: NONE | O9: 2025-12-18 | P9: lastDateToOrder | Q9: 2026-10-30
B10: N0002417D2201 | C10: small_craft | D10: IDV | E10: GRAVOIS ALUMINUM BOATS LLC | F10: 336612 | G10: 1940 | H10: 80.5 | I10: 14 | J10: 2022-05-31 | K10: -48.8 | L10: OVERDUE (ordering period closed, no successor seen) | M10: holders-only (FAR 16.5) | N10: NONE | O10: 2025-11-06 | P10: lastDateToOrder | Q10: 2027-06-30
B11: N0002415D2214 | C11: small_craft | D11: IDV | E11: METALCRAFT MARINE US, INC. | F11: 336612 | G11: 1940 | H11: 12.6 | I11: 12 | J11: 2022-09-30 | K11: -44.8 | L11: OVERDUE (ordering period closed, no successor seen) | M11: holders-only (FAR 16.5) | N11: NONE | O11: 2025-01-28 | P11: lastDateToOrder | Q11: 2026-03-02
B12: N0002417D2209 | C12: small_craft | D12: IDV | E12: GRAVOIS ALUMINUM BOATS LLC | F12: 336612 | G12: 1940 | H12: 117.8 | I12: 8 | J12: 2023-09-30 | K12: -32.8 | L12: OVERDUE (ordering period closed, no successor seen) | M12: holders-only (FAR 16.5) | N12: NONE | O12: 2025-06-17 | P12: lastDateToOrder | Q12: 2025-12-30
B13: N0002417D2217 | C13: small_craft | D13: IDV | E13: SNOW & COMPANY, INC. | F13: 336612 | G13: 1940 | H13: 35.3 | I13: 9 | J13: 2023-09-29 | K13: -32.8 | L13: OVERDUE (ordering period closed, no successor seen) | M13: holders-only (FAR 16.5) | N13: NONE | O13: 2025-02-24 | P13: lastDateToOrder | Q13: 2026-02-27
B14: N0002416D2215 | C14: small_craft | D14: IDV | E14: UNITED STATES MARINE INC | F14: 336612 | G14: 1940 | H14: 44 | I14: 13 | J14: 2023-09-30 | K14: -32.8 | L14: OVERDUE (ordering period closed, no successor seen) | M14: holders-only (FAR 16.5) | N14: NONE | O14: 2024-09-27 | P14: lastDateToOrder | Q14: 2027-02-10
B15: N0002419D2220 | C15: small_craft | D15: IDV | E15: RIBCRAFT USA, LLC | F15: 336612 | G15: 1940 | H15: 27.5 | I15: 7 | J15: 2024-04-03 | K15: -26.7 | L15: OVERDUE (ordering period closed, no successor seen) | M15: holders-only (FAR 16.5) | N15: NONE | O15: 2025-12-02 | P15: lastDateToOrder | Q15: 2026-09-30
B16: N0002420D2210 | C16: small_craft | D16: IDV | E16: RIBCRAFT USA, LLC | F16: 336612 | G16: 1940 | H16: 41.6 | I16: 8 | J16: 2025-08-11 | K16: -10.4 | L16: OVERDUE (ordering period closed, no successor seen) | M16: holders-only (FAR 16.5) | N16: NONE | O16: 2025-08-04 | P16: lastDateToOrder | Q16: 2028-06-27
B17: N0002421D2220 | C17: small_craft | D17: IDV | E17: UNITED STATES MARINE INC | F17: 336612 | G17: 1940 | H17: 40.6 | I17: 8 | J17: 2025-09-29 | K17: -8.8 | L17: OVERDUE (ordering period closed, no successor seen) | M17: holders-only (FAR 16.5) | N17: NONE | O17: 2025-09-26 | P17: lastDateToOrder | Q17: 2028-03-31
B18: N0010421CFA50 | C18: small_craft | D18: standalone | E18: ERIE FORGE & STEEL INC | F18: 336612 | G18: 2010 | H18: 8 | I18: 1 | J18: 2026-03-11 | K18: -3.4 | L18: OVERDUE (ordering period closed, no successor seen) | M18: open / standalone | N18: NONE | O18: 2025-12-15 | P18: ultimateCompletionDate | Q18: 2026-03-11
B19: N0002422C2223 | C19: small_craft | D19: standalone | E19: SILVER SHIPS, INC | F19: 336612 | G19: 1940 | H19: 16.2 | I19: 1 | J19: 2026-03-15 | K19: -3.3 | L19: OVERDUE (ordering period closed, no successor seen) | M19: open / standalone | N19: NONE | O19: 2025-07-07 | P19: ultimateCompletionDate | Q19: 2026-03-15
... B59: N0002422D6404 | C59: usv_core | D59: IDV | E59: THE JOHNS HOPKINS UNIVERSITY APPLIED PHYSICS LABORATORY LLC | F59: 541715 | G59: AC32 | H59: 35.2 | I59: 4 | J59: 2032-08-21 | K59: 74 | L59: horizon (24-36mo) | M59: holders-only (FAR 16.5) | N59: NONE | O59: 2026-03-09 | P59: lastDateToOrder | Q59: 2028-07-27

Sheet Teaming Edges
B2: Teaming Edges
B3: One row per reported first-tier subaward; sub amount in $M. A reported floor, not a census.
B5: §1 - First-tier subaward edges, prime to subcontractor (SAM/FSRS)
B7: Prime PIID | C7: Prime | D7: Prime UEI | E7: Sub Key | F7: Subcontractor | G7: Sub UEI | H7: Sub $M | I7: Sub Date | J7: Capability | K7: Lag (mo) | L7: Description
B8: N0002419C6402 | C8: TELEDYNE BROWN ENGINEERING, INC. | D8: FBRSJB6V4LW8 | E8: PAH8M4BJACA5 | F8: TELEDYNE INSTRUMENTS INC | G8: PAH8M4BJACA5 | H8: 8.259346 | I8: 2025-10-28 | J8: propulsion_power | K8: 1 | L8: Engineering materials
B9: N0001421C1009 | C9: RAYTHEON COMPANY | D9: VTEWM5QSE598 | E9: MFCTLU3MRXC8 | F9: EMPIRICAL SYSTEMS AEROSPACE, INC. | G9: MFCTLU3MRXC8 | H9: 5.507238 | I9: 2022-06-17 | J9: other_unclassified | K9: 0.8 | L9: NRE - Other.
B10: N0001421C1009 | C10: RAYTHEON COMPANY | D10: VTEWM5QSE598 | E10: U1ASEJJJKDP5 | F10: EMPIRICAL SYSTEMS AEROSPACE INC | G10: MFCTLU3MRXC8 | H10: 5.507238 | I10: 2022-06-17 | J10: other_unclassified | K10: 9.8 | L10: NRE - Other.
B11: N0001421C1009 | C11: RAYTHEON COMPANY | D11: VTEWM5QSE598 | E11: U1ASEJJJKDP5 | F11: EMPIRICAL SYSTEMS AEROSPACE INC | G11: MFCTLU3MRXC8 | H11: 5.401075 | I11: 2022-06-17 | J11: other_unclassified | K11: 22.2 | L11: NRE - All.
B12: N0001421C1009 | C12: RAYTHEON COMPANY | D12: VTEWM5QSE598 | E12: MFCTLU3MRXC8 | F12: EMPIRICAL SYSTEMS AEROSPACE, INC. | G12: MFCTLU3MRXC8 | H12: 5.362873 | I12: 2021-03-24 | J12: other_unclassified | K12: 17.3 | L12: Electromech-Mj Assys, NRE - Other.
B13: N0001421C1009 | C13: RAYTHEON COMPANY | D13: VTEWM5QSE598 | E13: U1ASEJJJKDP5 | F13: EMPIRICAL SYSTEMS AEROSPACE INC | G13: MFCTLU3MRXC8 | H13: 4.394075 | I13: 2021-03-24 | J13: integration_eng_svcs | K13: 37 | L13: Electromech-Mj Assys, NRE - All, Test Fixtures.
B14: N0001421C1009 | C14: RAYTHEON COMPANY | D14: VTEWM5QSE598 | E14: U1ASEJJJKDP5 | F14: EMPIRICAL SYSTEMS AEROSPACE INC | G14: MFCTLU3MRXC8 | H14: 4.394075 | I14: 2021-03-24 | J14: integration_eng_svcs | K14: 24.6 | L14: Electromech-Mj Assys, NRE - Other, Test Fixtures.
B15: N0003925F1019 | C15: TELEDYNE BROWN ENGINEERING, INC. | D15: FBRSJB6V4LW8 | E15: SQ2DSCE69F15 | F15: TELEDYNE TECHNOLOGIES INCORPORATED | G15: FNA3YNLZNM43 | H15: 3.189833 | I15: 2025-06-04 | J15: propulsion_power | K15: 1.8 | L15: Engineering services
B16: N0001418C2006 | C16: LEIDOS, INC. | D16: KTMAJCY6JXM3 | E16: JXUMFLGNSMP8 | F16: UNITED STATES MARINE, INC. | G16: JXUMFLGNSMP8 | H16: 3.114496 | I16: 2018-01-17 | J16: other_unclassified | K16: 24.9 | L16: PROCURED SERVICES BETWEEN 1/1/2020-1/31/2020 IN SUPPORT OF CONTRACT SOW.
B17: N0002424C2204 | C17: SAAB, INC | D17: H5FMLSGM29L1 | E17: NQEMKX3MRBV6 | F17: SAAB DYNAMICS AKTIEBOLAG | G17: NQEMKX3MRBV6 | H17: 2.6554618 | I17: 2025-03-27 | J17: other_unclassified | K17: 0.7 | L17: Multiple Parts for Double Eagle program
B18: N0002419C6402 | C18: TELEDYNE BROWN ENGINEERING, INC. | D18: FBRSJB6V4LW8 | E18: JNJDBJZLL2R7 | F18: EDGEONE LLC | G18: JNJDBJZLL2R7 | H18: 1.77289 | I18: 2025-10-27 | J18: propulsion_power | K18: 1 | L18: Engineering materials
B19: N0002419C6402 | C19: TELEDYNE BROWN ENGINEERING, INC. | D19: FBRSJB6V4LW8 | E19: SQ2DSCE69F15 | F19: TELEDYNE TECHNOLOGIES INCORPORATED | G19: PAH8M4BJACA5 | H19: 1.4351281 | I19: 2021-08-11 | J19: propulsion_power | K19: 0.7 | L19: Engineering services/materials
... B688: N0002417C4103 | C688: HUNTINGTON INGALLS INC | D688: WMXDDH6HJNA5 | E688: FZG7JRH6SLX4 | F688: VIRGINIA EQUIPMENT RENTAL COMPANY, INC. | G688: FZG7JRH6SLX4 | H688: 0 | I688: 2023-01-11 | J688: other_unclassified | K688: 1.3 | L688: PO 4500597304 PO Item No. 5-DELETED

Sheet Prime Concentration
B2: Prime Concentration
B3: Top recipients per tier; obligated in $M and tier share in percent. Sorted by share within tier.
B5: §1 - Prime concentration by market tier (top recipients)
B7: Tier | C7: Prime | D7: Obligated $M | E7: Tier Share %
B8: usv_core | C8: THE PENNSYLVANIA STATE UNIVERSITY | D8: 77.406512 | E8: 17.26
B9: usv_core | C9: LEIDOS, INC. | D9: 71.131893 | E9: 15.86
B10: usv_core | C10: THE JOHNS HOPKINS UNIVERSITY APPLIED PHYSICS LABORATORY LLC | D10: 65.088147 | E10: 14.51
B11: usv_core | C11: INNOVATIVE PROFESSIONAL SOLUTIONS, INC. | D11: 35.013807 | E11: 7.81
B12: usv_core | C12: RAYTHEON COMPANY | D12: 34.078855 | E12: 7.6
B13: usv_core | C13: AVIAN, LLC | D13: 32.370496 | E13: 7.22
B14: usv_core | C14: SERCO-IPS CORPORATION | D14: 29.704053 | E14: 6.62
B15: usv_core | C15: PERATON INC. | D15: 27.063456 | E15: 6.03
B16: usv_core | C16: EDO PROFESSIONAL SERVICES INC. | D16: 16.8 | E16: 3.75
B17: usv_core | C17: UNIVERSITY OF SOUTH CAROLINA | D17: 11.89 | E17: 2.65
B18: usv_core | C18: UNIVERSITY OF MAINE SYSTEM | D18: 9 | E18: 2.01
B19: usv_core | C19: COLSA CORP | D19: 4.5447997 | E19: 1.01
... B67: broad_maritime | C67: BAE SYSTEMS JACKSONVILLE SHIP REPAIR LLC | D67: 1792.061 | E67: 0.45

Sheet Market Tiers
B2: Market Tiers
B3: One row per discovered in-scope award; award amount in $M. Tier splits the addressable craft market from the excluded capital-ship tier (broad_maritime).
B5: §1 - In-scope sea-service awards by market tier (discovery universe)
B7: PIID | C7: Tier | D7: Award $M | E7: Recipient | F7: Matched Axes
B8: N0002417C2100 | C8: broad_maritime | D8: 34664.221 | E8: ELECTRIC BOAT CORPORATION | F8: naics:336611; psc:1905
B9: N0002417C2117 | C9: broad_maritime | D9: 30825.592 | E9: ELECTRIC BOAT CORPORATION | F9: psc:1905
B10: N0002412C2115 | C10: broad_maritime | D10: 20180.073 | E10: ELECTRIC BOAT CORPORATION | F10: naics:336611; psc:1905
B11: N0002409C2104 | C11: broad_maritime | D11: 16238.776 | E11: ELECTRIC BOAT CORPORATION | F11: naics:336611
B12: N0002416C2116 | C12: broad_maritime | D12: 11895.159 | E12: HUNTINGTON INGALLS INC | F12: naics:336611; psc:1905
B13: N0002406C2222 | C13: broad_maritime | D13: 10029.62 | E13: HUNTINGTON INGALLS INCORPORATED | F13: naics:336611
B14: N0002403C2101 | C14: broad_maritime | D14: 9397.3323 | E14: ELECTRIC BOAT CORPORATION | F14: naics:336611
B15: N0002423C2307 | C15: broad_maritime | D15: 6948.1902 | E15: HUNTINGTON INGALLS INCORPORATED | F15: naics:336611; psc:1905
B16: N0002418C2307 | C16: broad_maritime | D16: 6826.6802 | E16: HUNTINGTON INGALLS INCORPORATED | F16: naics:336611; psc:1905
B17: N0002408C2110 | C17: broad_maritime | D17: 6645.711 | E17: HUNTINGTON INGALLS INC | F17: naics:336611
B18: N0002402C2300 | C18: broad_maritime | D18: 5922.6454 | E18: NATIONAL STEEL AND SHIPBUILDING COMPANY | F18: naics:336611
B19: N0002416C2229 | C19: broad_maritime | D19: 5875.6345 | E19: NATIONAL STEEL AND SHIPBUILDING COMPANY | F19: naics:336611
... B5767: N3220513A6215 | C5767: broad_maritime | D5767: 0 | E5767: FAIRLEAD INTEGRATED POWER AND CONTROLS, LLC | F5767: psc:2090

Sheet Portal Notices
B2: Portal Notices
B3: The 669 maritime notices the portal showed, categorized by what is being bought. Subject usv_autonomy is ~2%; recurring sustainment (ship repair and parts) is ~65%.
B5: §1 - SAM Opportunities notices on hand, by subject (Finding 1)
B7: Notice ID | C7: Type | D7: Posted | E7: Buyer | F7: Subject | G7: NAICS | H7: PSC | I7: Title | J7: Solicitation
B8: adb09927bf6045819455cddc19330b4a | C8: Presolicitation | D8: 2025-11-05 | E8: Navy/USMC | F8: usv_autonomy | G8: 541330 | H8: J059 | I8: Unmanned Maritime Systems Support (UMSS) | J8: N66001_25_R_0024
B9: 9deb06ebb8cd4f6db5d975da1cfa2782 | C9: Solicitation | D9: 2025-12-10 | E9: Navy/USMC | F9: usv_autonomy | G9: 541330 | H9: J059 | I9: Unmanned Maritime Systems Support (UMSS) | J9: N6600126R0018
B10: 930b288442584843b94ec1d27d2279fe | C10: Solicitation | D10: 2026-01-08 | E10: Navy/USMC | F10: usv_autonomy | G10: 541330 | H10: R425 | I10: Unmanned Maritime Systems (UMS) Support | J10: N6133126R3102
B11: 42aee566e9c74f5ea089d2b6e567ca68 | C11: Solicitation | D11: 2026-05-06 | E11: Navy/USMC | F11: usv_autonomy | G11: 541512 | H11: 7G22 | I11: Area of Interest (AOI): Information and Communications Technology (ICT) for Unmanned Surface Vessels (USV) | J11: N0003926RA005
B12: dec45644b193428db38e9ef0df7cada9 | C12: Solicitation | D12: 2026-06-08 | E12: Civil/Other | F12: usv_autonomy | G12: 334511 | H12: 6680 | I12: USV FOR MEAS and BATHYMETRY SURVEYS IAW SALIENTS | J12: 140G0126Q0169
B13: 583abe432ccb4cddb523c8c3e672ded5 | C13: Special Notice | D13: 2026-06-11 | E13: Other DoD | F13: usv_autonomy | I13: Federal Business Opportunities posting Request for Information Assured Access to Maritime Autonomous Surface Ships | J13: USTC2026001
B14: 63623804dc004f36b804373f0fa98c4e | C14: Special Notice | D14: 2026-06-11 | E14: Navy/USMC | F14: usv_autonomy | G14: 541715 | I14: NSWC-PHD MATAC OTA Request for Solutions: USV C2 laboratory Expansion Project | J14: REQ-AS-002
B15: 8fc07bff4f6745b59168bd6cf65ad4ae | C15: Solicitation | D15: 2026-03-26 | E15: Navy/USMC | F15: usv_autonomy | G15: 541330 | H15: H216 | I15: NAWCAD (WOLF) Ship and Air Integrated Warfare Division Small Unmanned Aircraft Systems (SUAS) Reusable Architecture (SRA) | J15: N0042126R1006
B16: 5a5b3b20ce7447a0b3d7014a5c857992 | C16: Special Notice | D16: 2026-05-18 | E16: Army | F16: usv_autonomy | I16: Capability Program Executive (CPE) Mission Autonomy Commercial Solution Opening (CSO) Area of Interest 002 Bridge Erection Boat (BEB) Autonomous Operations | J16: W912CH26SC003AoI002
B17: c9a5ea2425964b6a8c66d8fe9c7fc65c | C17: Combined Synopsis/Solicitation | D17: 2026-06-01 | E17: Navy/USMC | F17: usv_autonomy | G17: 541330 | H17: R425 | I17: Sole Source to Woods Hole Oceanographic Institute for Unmanned Underwater Vehicle Resilience In-Water Test Support per attachments | J17: N61331-26-Q-KS34
B18: 0ba4990fa76747cfb3d57ea49991bf5b | C18: Special Notice | D18: 2026-06-11 | E18: Navy/USMC | F18: usv_autonomy | I18: Subsea and Seabed Warfare and Robotic Autonomous Systems Industry Day | J18: N00253-ID-SSW-RAS-06152026
B19: 0530ce59a5084be0b0f720a7ef4daaff | C19: Solicitation | D19: 2026-06-08 | E19: Navy/USMC | F19: usv_autonomy | G19: 541330 | H19: R702 | I19: OCEAN FLOOR MAPPING WITH LONG-ENDURANCE UNMANNED SYSTEMS | J19: N0018926RL021
B20: a59703eddd0a4e02b05461557049744d | C20: Sources Sought | D20: 2026-06-11 | E20: Coast Guard | F20: usv_autonomy | G20: 541715 | H20: AJ12 | I20: Micro-Uncrewed (UxS) Systems for Dangerous Vessel Compartment Inspections | J20: 70Z02326RFI0003
B21: a6f064c736744b438ec14d905939675f | C21: Special Notice | D21: 2025-12-17 | E21: Navy/USMC | F21: ship_repair_maintenance | G21: 336611 | H21: J020 | I21: Domestic Private Sector CMAV Workload Estimate | J21: CNRMC-CMAV-Projection
B22: 6e5cad2ba2254abdac40550d7a458eae | C22: Special Notice | D22: 2025-12-17 | E22: Navy/USMC | F22: ship_repair_maintenance | G22: 336611 | H22: J020 | I22: Private Sector Workload Forecast Material for Public Website | J22: CNRMC-Projection2
B23: cfda51b224934fa2be7d2904b485ae56 | C23: Solicitation | D23: 2025-06-19 | E23: Navy/USMC | F23: ship_repair_maintenance | G23: 336611 | H23: J999 | I23: USNS EARL WARREN (T-AO 207) POST SHAKEDOWN AVAILABILITY Solicitation | J23: N3220525R4020
B24: d834469937c44d2cb2612b1315591e75 | C24: Solicitation | D24: 2025-06-20 | E24: Navy/USMC | F24: ship_repair_maintenance | G24: 336611 | H24: J019 | I24: Maintenance, Repair, and Preservation of Bangor Caisson 1 Prime | J24: N4523A25R6002
B25: 3dcc446cb6e9406dbdc6ebf40a77edc7 | C25: Combined Synopsis/Solicitation | D25: 2025-06-23 | E25: Army | F25: other | G25: 336611 | H25: 1920 | I25: Custom electrofishing boat | J25: W911S225U0854
B26: 056f2d78a40c4369a5919b88bb5be310 | C26: Combined Synopsis/Solicitation | D26: 2025-06-24 | E26: Army | F26: vessel_procurement | G26: 336612 | H26: 1940 | I26: Jet Skis | J26: W911S225U0978
B27: e2a3d2a59815454788908eac0e5d3739 | C27: Solicitation | D27: 2025-06-23 | E27: Navy/USMC | F27: ship_repair_maintenance | G27: 336611 | H27: J998 | I27: USNS ROBERT E. SIMANEK, PSA | J27: N3220525R4083
B28: d7af01a351cc4ae8a10143c52a489209 | C28: Solicitation | D28: 2025-07-08 | E28: Army | F28: ship_repair_maintenance | G28: 336611 | H28: J019 | I28: Army Watercraft Sustainment Maintenance (AWSM) Program Zone 1 CONUS (UPDATE 0008)(AMENDMENT 0005) | J28: W912CH25RA005
B29: 6deeb3980f8b4b61bdc8d17fc1184993 | C29: Solicitation | D29: 2025-07-08 | E29: Army | F29: ship_repair_maintenance | G29: 336611 | H29: J019 | I29: Army Watercraft Sustainment Maintenance (AWSM) Program Zone 2 OCONUS (UPDATE 0008)(AMENDMENT 0005) | J29: W912CH25RA006
B30: 4a6cbf883a5a452c8d74b19a16782e5b | C30: Solicitation | D30: 2025-07-31 | E30: Navy/USMC | F30: ship_repair_maintenance | G30: 336611 | H30: J998 | I30: East Coast General Ship Repair IDIQ | J30: N3220522R0012
... B134: b86d1a6ec361446a88c1c05be5d48ea0 | C134: Combined Synopsis/Solicitation | D134: 2026-05-22 | E134: Navy/USMC | F134: ship_repair_maintenance | G134: 336611 | H134: J030 | I134: Propeller Cap Services | J134: N6449826Q5157
B135: d20ebc5e518244fd98da95104138ebcc | C135: Special Notice | D135: 2026-05-28 | E135: Navy/USMC | F135: other | G135: 336611 | I135: USS SAVANNAH FY26 DSRA RCC 4N
B136: 28e94582b02642db8a51b66597c05e4b | C136: Combined Synopsis/Solicitation | D136: 2026-04-20 | E136: Navy/USMC | F136: ship_repair_maintenance | G136: 336611 | H136: J020 | I136: Restore and upgrade the Secondary Propulsion Unit Rotary Deployment Mechanism (RDM) | J136: N3904026Q0003
B137: e6c2fa3b6a3b46588a0b5fd962cdbfea | C137: Presolicitation | D137: 2026-05-07 | E137: Coast Guard | F137: vessel_procurement | G137: 336611 | H137: 1925 | I137: Pre-Solicitation Notice - Homeland Security Cutter - Light (HSC-L) | J137: 70Z02326R93280004
B138: 2d0814ee7bed4947a8d6992030a979e2 | C138: Sources Sought | D138: 2026-05-14 | E138: Navy/USMC | F138: ship_repair_maintenance | G138: 336611 | H138: J998 | I138: USS WICHITA (LCS 13) FY27 DSRA | J138: N0002426R4415
B139: 0c236904d47346b7be617406fecf8907 | C139: Sources Sought | D139: 2026-05-14 | E139: Coast Guard | F139: ship_repair_maintenance | G139: 336611 | H139: J998 | I139: DOCK-SIDE (DS): CGC BEAR AA FY27 | J139: 70Z08026SCGCBEARAA
B140: 54a6e04790564ee0864b3b7c9ba8e68e | C140: Combined Synopsis/Solicitation | D140: 2026-05-19 | E140: Coast Guard | F140: ship_repair_maintenance | G140: 336611 | H140: J020 | I140: 52000QR260024183- CGC Escanaba 28VDC Rectifier | J140: 52000QR260024183
B141: ebed95f09a254d72963bd0e462cf134f | C141: Special Notice | D141: 2026-05-22 | E141: Civil/Other | F141: ship_repair_maintenance | G141: 336611 | H141: J020 | I141: NOTICE OF INTENT TO SOLE SOURCE | J141: 1333MK26Q0070
B142: f46e9b6aeb1e41f790c687ea7c3f5f38 | C142: Sources Sought | D142: 2026-05-26 | E142: Coast Guard | F142: ship_repair_maintenance | G142: 336611 | H142: J998 | I142: USCG STA MARATHON (45616) FY26 DRYDOCK REPAIRS | J142: 70Z04026SSBPL5265
B143: 1d75edee87ec4853b3ecf37354cf23ca | C143: Solicitation | D143: 2026-05-28 | E143: Navy/USMC | F143: ship_repair_maintenance | G143: 336611 | H143: J998 | I143: TANK LEVEL INDICATOR ATTENDANCE | J143: N0040626Q0188
B144: db0cecbefaf74cb4872dd1534b8e6fa9 | C144: Solicitation | D144: 2026-05-15 | E144: Navy/USMC | F144: ship_repair_maintenance | G144: 336611 | H144: J999 | I144: USS AMERICA (LHA 6) FY26 DSRA A00018 Redacted J&A_RCC 116N | J144: N0002425C4404
B145: 9eaf8e12396b451fb42cf176960cabe7 | C145: Solicitation | D145: 2026-05-15 | E145: Navy/USMC | F145: ship_repair_maintenance | G145: 336611 | H145: J999 | I145: USS AMERICA (LHA 6) FY26 DSRA A00021 Redacted J&A | J145: N0002425C4404_N55235260001
B146: 887323da44474b6983f77b11280e9969 | C146: Solicitation | D146: 2026-05-15 | E146: Navy/USMC | F146: ship_repair_maintenance | G146: 336611 | H146: J999 | I146: USS AMERICA (LHA 6) FY26 DSRA A00020 Redacted J&A_RCC 259 | J146: N0002425C4404_A00020
...

Sheet Award-Opportunity Match
B2: Award-Opportunity Match
B3: Each addressable award and whether a matching notice exists. In Window flags the portal's 12-month posting window; Match Level NONE = dark (no notice).
B5: §1 - Addressable awards matched to SAM Opportunities notices (incompleteness)
B7: PIID | C7: Parent IDV | D7: Tier | E7: Recipient | F7: Award Type | G7: Obligation $M | H7: Date Signed | I7: In Window | J7: Solicitation | K7: Match Level | L7: Matched Notice
B8: N0002419C2210 | D8: other_small | E8: BOLLINGER MISSISSIPPI SHIPBUILDING, LLC | F8: D | G8: 2019.7384 | H8: 2019-04-23 | I8: no | J8: N0002418R2210 | K8: NONE
B9: N0002409C2229 | D9: other_small | E9: NATIONAL STEEL AND SHIPBUILDING COMPANY | F9: D | G9: 1965.3757 | H9: 2009-02-13 | I9: no | J9: N0002408R2270 | K9: NONE
B10: N0002404C2204 | D10: small_craft | E10: HUNTINGTON INGALLS INCORPORATED | F10: D | G10: 1304.5306 | H10: 2003-11-25 | I10: no | K10: NONE
B11: N0002423C2203 | D11: other_small | E11: AUSTAL USA, LLC | F11: D | G11: 631.81573 | H11: 2023-05-18 | I11: no | J11: N0002422R2203 | K11: NONE
B12: N0002418C2207 | D12: other_small | E12: BOLLINGER SHIPYARDS LOCKPORT, L.L.C. | F12: D | G12: 423.96604 | H12: 2018-03-16 | I12: no | J12: N0002417R2207 | K12: NONE
B13: N0002421C2209 | D13: other_small | E13: AUSTAL USA, LLC | F13: D | G13: 383.61313 | H13: 2021-06-03 | I13: no | J13: N0002421R2209 | K13: NONE
B14: N0002419C6402 | D14: other_small | E14: TELEDYNE BROWN ENGINEERING, INC. | F14: D | G14: 242.75469 | H14: 2019-09-27 | I14: no | J14: N0002419R6402 | K14: NONE
B15: N0002409C2256 | D15: small_craft | E15: SWIFTSHIPS SHIPBUILDERS, L.L.C. | F15: D | G15: 240.11744 | H15: 2009-09-25 | I15: no | J15: N0002409R2256 | K15: NONE
B16: N0002421C2201 | D16: small_craft | E16: SAFE BOATS INTERNATIONAL LLC | F16: D | G16: 173.87721 | H16: 2020-12-31 | I16: no | J16: N0002421R2200 | K16: NONE
B17: N0002419C2208 | D17: other_small | E17: BOLLINGER MISSISSIPPI SHIPBUILDING, LLC | F17: D | G17: 166.50348 | H17: 2018-11-16 | I17: no | J17: N0002418R2208 | K17: NONE
B18: N0002410C2201 | D18: other_small | E18: DAKOTA CREEK INDUSTRIES INC | F18: D | G18: 153.64051 | H18: 2010-01-27 | I18: no | J18: N0002409R2212 | K18: NONE
B19: N6238715C2502 | D19: small_craft | E19: HORNBECK OFFSHORE SERVICES LLC | F19: D | G19: 152 | H19: 2015-02-25 | I19: no | K19: NONE
B20: N0002422C6305 | D20: small_craft | E20: BOLLINGER SHIPYARDS LOCKPORT, L.L.C. | F20: D | G20: 116.47118 | H20: 2022-04-08 | I20: no | J20: N0002421R6300 | K20: NONE
B21: N0002423C6308 | D21: small_craft | E21: HII UNMANNED SYSTEMS, INC | F21: D | G21: 113.25855 | H21: 2023-09-28 | I21: no | J21: N0002423R6308 | K21: NONE
B22: N0002422C2505 | D22: other_small | E22: NATIONAL STEEL AND SHIPBUILDING COMPANY | F22: D | G22: 98.697872 | H22: 2022-04-04 | I22: no | J22: N0002421R2504 | K22: NONE
B23: N0002410C2239 | D23: other_small | E23: BOLLINGER MISSISSIPPI SHIPBUILDING, LLC | F23: D | G23: 97.587905 | H23: 2009-12-22 | I23: no | J23: N0002409R2239 | K23: NONE
B24: N0002418C2205 | D24: other_small | E24: DAKOTA CREEK INDUSTRIES INC | F24: D | G24: 81.848335 | H24: 2018-07-13 | I24: no | J24: N0002417R2205 | K24: NONE
B25: N0002409C2252 | D25: small_craft | E25: UNITED STATES MARINE INC | F25: D | G25: 77.276507 | H25: 2009-05-26 | I25: no | K25: NONE
B26: N0002407C2236 | D26: small_craft | E26: C & G BOAT WORKS, INC. | F26: D | G26: 68.288516 | H26: 2007-06-20 | I26: no | K26: NONE
B27: H9240520F0022 | C27: H9222211D0080 | D27: small_craft | E27: VIGOR WORKS LLC | F27: C | G27: 66.875826 | H27: 2020-06-26 | I27: no | J27: H9222211R0001 | K27: NONE
B28: N0002414C2230 | D28: small_craft | E28: SAFE BOATS INTERNATIONAL LLC | F28: D | G28: 58.219421 | H28: 2014-07-02 | I28: no | J28: N0002414R2230 | K28: NONE
B29: N3220517C4406 | D29: other_small | E29: VIGOR MARINE LLC | F29: D | G29: 55.478973 | H29: 2017-02-17 | I29: no | J29: N3220516R4406 | K29: NONE
B30: N0002423C2201 | D30: small_craft | E30: RECONCRAFT, LLC | F30: D | G30: 55.048603 | H30: 2023-04-24 | I30: no | J30: N0002423R2201 | K30: NONE
B31: N0002418C2223 | D31: small_craft | E31: MARINE GROUP BOAT WORKS, LLC | F31: D | G31: 53.456821 | H31: 2017-12-15 | I31: no | J31: N0002417R2223 | K31: NONE
B32: N0002419F8406 | C32: N0002418D6401 | D32: usv_core | E32: THE PENNSYLVANIA STATE UNIVERSITY | F32: C | G32: 46.438408 | H32: 2019-01-04 | I32: no | K32: NONE
B33: N0001418C2006 | D33: usv_core | E33: LEIDOS, INC. | F33: D | G33: 43.559069 | H33: 2017-12-15 | I33: no | J33: N0001417SB001 | K33: NONE
B34: N0002412F2223 | C34: GS07F0038H | D34: small_craft | E34: SAFE BOATS INTERNATIONAL LLC | F34: C | G34: 42.755221 | H34: 2012-05-14 | I34: no | K34: NONE
B35: N0002423F2201 | C35: 47QSWA18D009G | D35: small_craft | E35: SILVER SHIPS, INC | F35: C | G35: 42.345865 | H35: 2023-06-01 | I35: no | J35: N0002423Q2201 | K35: NONE
B36: N0010424CZA51 | D36: small_craft | E36: ERIE FORGE & STEEL INC | F36: D | G36: 40.266044 | H36: 2024-09-13 | I36: no | J36: N0010424RZA83 | K36: NONE
B37: N6133120C0018 | D37: other_small | E37: YULISTA SUPPORT SERVICES LLC | F37: D | G37: 37.951356 | H37: 2020-09-18 | I37: no | J37: N6133120R0004 | K37: NONE
B38: N0002409C2210 | D38: small_craft | E38: SWIFTSHIPS SHIPBUILDERS, L.L.C. | F38: D | G38: 35.557215 | H38: 2008-11-07 | I38: no | J38: N0002409R2210 | K38: NONE
B39: N0002423C2205 | D39: small_craft | E39: RECONCRAFT, LLC | F39: D | G39: 33.450237 | H39: 2023-05-10 | I39: no | J39: N0002423R2205 | K39: NONE
B40: N0001421C1009 | D40: usv_core | E40: RAYTHEON COMPANY | F40: D | G40: 33.140146 | H40: 2021-02-26 | I40: no | J40: N0001420SB001 | K40: NONE
B41: N6133120F3009 | C41: N0017819D7206 | D41: usv_core | E41: AVIAN, LLC | F41: C | G41: 32.370496 | H41: 2020-08-19 | I41: no | J41: N6133119R3500 | K41: NONE
B42: N0002422F8306 | C42: N0002418D6401 | D42: usv_core | E42: THE PENNSYLVANIA STATE UNIVERSITY | F42: C | G42: 30.698104 | H42: 2021-12-02 | I42: no | K42: NONE
B43: N0002419F22X1 | C43: N0002417D2209 | D43: small_craft | E43: GRAVOIS ALUMINUM BOATS LLC | F43: C | G43: 30.204744 | H43: 2019-03-07 | I43: no | J43: N0002417R2209 | K43: NONE
...

Sheet Backtest Events
B2: Backtest Events
B3: Each row is a predecessor-successor recompete pair. t-6/12/18 = whether the predecessor's then-known FPDS clock put it in the 36-month horizon at that freeze (no look-ahead). Event Class separates true turnovers from parallel vehicles a builder held at once.
B5: §1 - Recompete events: would the radar have flagged each, point-in-time?
B7: Builder | C7: Predecessor | D7: Successor | E7: Succ Award | F7: Pred Close | G7: Close vs Succ (mo) | H7: Event Class | I7: t-6 | J7: t-12 | K7: t-18 | L7: Clock Known @ t-12 | M7: Lead (mo) | N7: Clock Extended
B8: METALCRAFT | C8: N0002413D2202 | D8: N0002415D2214 | E8: 2015-09-30 | F8: 2018-02-22 | G8: 28.8 | H8: parallel | I8: Y | J8: N | K8: N | L8: 2018-02-22 | M8: 7.2 | N8: N
B9: GRAVOISALU | C9: N0002413D2253 | D9: N0002414D2207 | E9: 2016-06-01 | F9: 2018-06-12 | G9: 24.4 | H9: parallel | I9: Y | J9: N | K9: N | L9: 2018-06-12 | M9: 11.7 | N9: N
B10: UNITEDSTAT | C10: N0002414D2203 | D10: N0002416D2215 | E10: 2016-09-29 | F10: 2019-08-07 | G10: 34.3 | H10: parallel | I10: N | J10: N | K10: N | L10: 2019-08-07 | M10: 1.7 | N10: N
B11: WILLARDMAR | C11: GS07F0123H | D11: N0002417D2200 | E11: 2017-04-03 | F11: 2018-09-14 | G11: 17.4 | H11: parallel | I11: Y | J11: Y | K11: Y | L11: 2018-09-14 | M11: 18.7 | N11: N
B12: MODUTECHMA | C12: N0002416D2211 | D12: GS07F5488P | E12: 2019-08-16 | F12: 2021-08-30 | G12: 24.5 | H12: parallel | I12: Y | J12: N | K12: N | L12: 2021-08-30 | M12: 11.6 | N12: N
B13: UNITEDSTAT | C13: N0002416D2215 | D13: N0002421D2220 | E13: 2021-09-29 | F13: 2023-09-30 | G13: 24 | H13: parallel | I13: Y | J13: Y | K13: Y | L13: 2021-09-30 | M13: 12 | N13: Y
B14: SILVERSHIP | C14: N0002414D2205 | D14: N0002421D2205 | E14: 2021-09-30 | F14: 2018-11-21 | G14: -34.3 | H14: lapsed-rebuy | I14: Y | J14: Y | K14: Y | L14: 2018-11-21 | M14: 70.4 | N14: N
B15: SNOWCOMPAN | C15: N0002417D2217 | D15: N0002421D2255 | E15: 2021-09-30 | F15: 2023-09-29 | G15: 24 | H15: parallel | I15: Y | J15: N | K15: N | L15: 2023-09-29 | M15: 12.1 | N15: N
B16: METALCRAFT | C16: N0002415D2214 | D16: N0002422D2270 | E16: 2022-03-09 | F16: 2022-09-30 | G16: 6.7 | H16: recompete | I16: Y | J16: Y | K16: Y | L16: 2022-09-30 | M16: 29.4 | N16: N
B17: RIBCRAFTUS | C17: N0002420D2210 | D17: N0002423D2224 | E17: 2023-02-09 | F17: 2025-08-11 | G17: 30.1 | H17: parallel | I17: N | J17: N | K17: N | L17: 2025-08-11 | M17: 6 | N17: N
B18: GRAVOISALU | C18: N0002417D2209 | D18: N0002424D2275 | E18: 2024-05-16 | F18: 2023-09-30 | G18: -7.5 | H18: recompete | I18: Y | J18: Y | K18: Y | L18: 2023-09-30 | M18: 43.6 | N18: N

Sheet PoP Timeline
B2: PoP Timeline
B3: Each row is a distinct lastDateToOrder value and the date a contract action first recorded it; the clock was on record years ahead, and a later mod extending it shows as EXTENDED.
B5: §1 - Ordering-period clock history (point-in-time, per FPDS action)
B7: Vehicle PIID | C7: Role | D7: Clock Recorded | E7: Mod | F7: Last Date To Order | G7: Event
B8: GS07F0123H | C8: predecessor | D8: 1998-09-15 | E8: 0 | F8: 2009-03-14 | G8: base clock
B9: GS07F0123H | C9: predecessor | D9: 2009-03-02 | E9: 2 | F9: 2013-09-14 | G9: EXTENDED / changed
B10: GS07F0123H | C10: predecessor | D10: 2013-07-16 | E10: 42 | F10: 2018-09-14 | G10: EXTENDED / changed
B11: GS07F5488P | C11: successor | D11: 2003-12-09 | E11: 0 | F11: 2008-12-08 | G11: base clock
B12: GS07F5488P | C12: successor | D12: 2008-11-06 | E12: 2 | F12: 2013-12-08 | G12: EXTENDED / changed
B13: GS07F5488P | C13: successor | D13: 2013-10-04 | E13: PO0031EXERCISEOPTION | F13: 2018-12-08 | G13: EXTENDED / changed
B14: GS07F5488P | C14: successor | D14: 2018-08-06 | E14: PGA617 | F14: 2023-12-08 | G14: EXTENDED / changed
B15: GS07F5488P | C15: successor | D15: 2018-08-06 | E15: PMA617 | F15: 2018-12-08 | G15: EXTENDED / changed
B16: GS07F5488P | C16: successor | D16: 2018-12-20 | E16: PMA707 | F16: 2023-12-08 | G16: EXTENDED / changed
B17: N0002413D2202 | C17: predecessor | D17: 2013-02-21 | E17: 0 | F17: 2018-02-22 | G17: base clock
B18: N0002413D2253 | C18: predecessor | D18: 2013-06-13 | E18: 0 | F18: 2018-06-12 | G18: base clock
... B36: N0002424D2275 | C36: successor | D36: 2024-05-16 | E36: 0 | F36: 2031-05-16 | G36: base clock
